 <!-- .........................................................TETHER STUFF.................................................................... -->
 
 <link name="link_tether_1">
    <visual>
      <geometry>
        <cylinder length="0.02" radius="0.005"/>
      </geometry>
      <origin rpy="0 0 0" xyz="-0.0 0.0 0"/>
      <material name="grey"/>
    </visual>
    <collision>
      <geometry>
        <cylinder length="0.02" radius="0.005"/>
      </geometry>
      <origin rpy="0 0 0" xyz="-0.0 0.0 0"/>
    </collision>
    <inertial>
      <mass value="0.005"/>
      <inertia ixx="1.9791666666666667e-07" ixy="0" ixz="0" iyy="1.9791666666666667e-07" iyz="0" izz="6.250000000000001e-08"/>
      <origin rpy="0 0 0" xyz="-0.0 0.0 0"/>
    </inertial>
  </link>

  <joint name="joint_tether_1" type="continuous">
    <origin rpy="0.0 0.0 0.0" xyz="-0.10 0.0 1.5"/>
    <axis xyz="0 0 1"/>
    <parent link="uav_platform"/>
    <child link="link_tether_1"/>
  </joint>

  <gazebo reference="tether_1">
    <material>Gazebo/Grey</material>
    <gravity>True</gravity>
    <selfCollide>True</selfCollide>
    <maxContacts>10</maxContacts>
    <dampingFactor>0.0</dampingFactor>
    <maxVel>0.0</maxVel>
    <minDepth>0.0</minDepth>
    <mu1>1.000000</mu1>
    <mu2>1.000000</mu2>
  </gazebo>

  <link name="link_tether_2">
    <visual>
      <geometry>
        <cylinder length="0.02" radius="0.005"/>
      </geometry>
      <origin rpy="0 0 0" xyz="-0.0 0.0 0"/>
      <material name="grey"/>
    </visual>
    <collision>
      <geometry>
        <cylinder length="0.02" radius="0.005"/>
      </geometry>
      <origin rpy="0 0 0" xyz="-0.0 0.0 0"/>
    </collision>
    <inertial>
      <mass value="0.005"/>
      <inertia ixx="1.9791666666666667e-07" ixy="0" ixz="0" iyy="1.9791666666666667e-07" iyz="0" izz="6.250000000000001e-08"/>
      <origin rpy="0 0 0" xyz="-0.0 0.0 0"/>
    </inertial>
  </link>

  <joint name="joint_tether_2" type="continuous">
    <origin rpy="0.0 0.0 0.0" xyz="0.0 0.0 0.02"/>
    <axis xyz="0 1 1"/>
    <parent link="link_tether_1"/>
    <child link="link_tether_2"/>
  </joint>

  <gazebo reference="tether_2">
    <material>Gazebo/Grey</material>
    <gravity>True</gravity>
    <selfCollide>True</selfCollide>
    <maxContacts>10</maxContacts>
    <dampingFactor>0.0</dampingFactor>
    <maxVel>0.0</maxVel>
    <minDepth>0.0</minDepth>
    <mu1>1.000000</mu1>
    <mu2>1.000000</mu2>
  </gazebo>

  <link name="link_tether_3">
    <visual>
      <geometry>
        <cylinder length="0.02" radius="0.005"/>
      </geometry>
      <origin rpy="0 0 0" xyz="-0.0 0.0 0"/>
      <material name="grey"/>
    </visual>
    <collision>
      <geometry>
        <cylinder length="0.02" radius="0.005"/>
      </geometry>
      <origin rpy="0 0 0" xyz="-0.0 0.0 0"/>
    </collision>
    <inertial>
      <mass value="0.005"/>
      <inertia ixx="1.9791666666666667e-07" ixy="0" ixz="0" iyy="1.9791666666666667e-07" iyz="0" izz="6.250000000000001e-08"/>
      <origin rpy="0 0 0" xyz="-0.0 0.0 0"/>
    </inertial>
  </link>

  <joint name="joint_tether_3" type="continuous">
    <origin rpy="0.0 0.0 0.0" xyz="0.0 0.0 0.02"/>
    <axis xyz="0 1 1"/>
    <parent link="link_tether_2"/>
    <child link="link_tether_3"/>
  </joint>

  <gazebo reference="tether_3">
    <material>Gazebo/Grey</material>
    <gravity>True</gravity>
    <selfCollide>True</selfCollide>
    <maxContacts>10</maxContacts>
    <dampingFactor>0.0</dampingFactor>
    <maxVel>0.0</maxVel>
    <minDepth>0.0</minDepth>
    <mu1>1.000000</mu1>
    <mu2>1.000000</mu2>
  </gazebo>

  <link name="link_tether_4">
    <visual>
      <geometry>
        <cylinder length="0.02" radius="0.005"/>
      </geometry>
      <origin rpy="0 0 0" xyz="-0.0 0.0 0"/>
      <material name="grey"/>
    </visual>
    <collision>
      <geometry>
        <cylinder length="0.02" radius="0.005"/>
      </geometry>
      <origin rpy="0 0 0" xyz="-0.0 0.0 0"/>
    </collision>
    <inertial>
      <mass value="0.005"/>
      <inertia ixx="1.9791666666666667e-07" ixy="0" ixz="0" iyy="1.9791666666666667e-07" iyz="0" izz="6.250000000000001e-08"/>
      <origin rpy="0 0 0" xyz="-0.0 0.0 0"/>
    </inertial>
  </link>

  <joint name="joint_tether_4" type="continuous">
    <origin rpy="0.0 0.0 0.0" xyz="0.0 0.0 0.02"/>
    <axis xyz="0 1 1"/>
    <parent link="link_tether_3"/>
    <child link="link_tether_4"/>
  </joint>

  <gazebo reference="tether_4">
    <material>Gazebo/Grey</material>
    <gravity>True</gravity>
    <selfCollide>True</selfCollide>
    <maxContacts>10</maxContacts>
    <dampingFactor>0.0</dampingFactor>
    <maxVel>0.0</maxVel>
    <minDepth>0.0</minDepth>
    <mu1>1.000000</mu1>
    <mu2>1.000000</mu2>
  </gazebo>

  <link name="link_tether_5">
    <visual>
      <geometry>
        <cylinder length="0.02" radius="0.005"/>
      </geometry>
      <origin rpy="0 0 0" xyz="-0.0 0.0 0"/>
      <material name="grey"/>
    </visual>
    <collision>
      <geometry>
        <cylinder length="0.02" radius="0.005"/>
      </geometry>
      <origin rpy="0 0 0" xyz="-0.0 0.0 0"/>
    </collision>
    <inertial>
      <mass value="0.005"/>
      <inertia ixx="1.9791666666666667e-07" ixy="0" ixz="0" iyy="1.9791666666666667e-07" iyz="0" izz="6.250000000000001e-08"/>
      <origin rpy="0 0 0" xyz="-0.0 0.0 0"/>
    </inertial>
  </link>

  <joint name="joint_tether_5" type="continuous">
    <origin rpy="0.0 0.0 0.0" xyz="0.0 0.0 0.02"/>
    <axis xyz="0 1 1"/>
    <parent link="link_tether_4"/>
    <child link="link_tether_5"/>
  </joint>

  <gazebo reference="tether_5">
    <material>Gazebo/Grey</material>
    <gravity>True</gravity>
    <selfCollide>True</selfCollide>
    <maxContacts>10</maxContacts>
    <dampingFactor>0.0</dampingFactor>
    <maxVel>0.0</maxVel>
    <minDepth>0.0</minDepth>
    <mu1>1.000000</mu1>
    <mu2>1.000000</mu2>
  </gazebo>

  <link name="link_tether_6">
    <visual>
      <geometry>
        <cylinder length="0.02" radius="0.005"/>
      </geometry>
      <origin rpy="0 0 0" xyz="-0.0 0.0 0"/>
      <material name="grey"/>
    </visual>
    <collision>
      <geometry>
        <cylinder length="0.02" radius="0.005"/>
      </geometry>
      <origin rpy="0 0 0" xyz="-0.0 0.0 0"/>
    </collision>
    <inertial>
      <mass value="0.005"/>
      <inertia ixx="1.9791666666666667e-07" ixy="0" ixz="0" iyy="1.9791666666666667e-07" iyz="0" izz="6.250000000000001e-08"/>
      <origin rpy="0 0 0" xyz="-0.0 0.0 0"/>
    </inertial>
  </link>

  <joint name="joint_tether_6" type="continuous">
    <origin rpy="0.0 0.0 0.0" xyz="0.0 0.0 0.02"/>
    <axis xyz="0 1 1"/>
    <parent link="link_tether_5"/>
    <child link="link_tether_6"/>
  </joint>

  <gazebo reference="tether_6">
    <material>Gazebo/Grey</material>
    <gravity>True</gravity>
    <selfCollide>True</selfCollide>
    <maxContacts>10</maxContacts>
    <dampingFactor>0.0</dampingFactor>
    <maxVel>0.0</maxVel>
    <minDepth>0.0</minDepth>
    <mu1>1.000000</mu1>
    <mu2>1.000000</mu2>
  </gazebo>

  <link name="link_tether_7">
    <visual>
      <geometry>
        <cylinder length="0.02" radius="0.005"/>
      </geometry>
      <origin rpy="0 0 0" xyz="-0.0 0.0 0"/>
      <material name="grey"/>
    </visual>
    <collision>
      <geometry>
        <cylinder length="0.02" radius="0.005"/>
      </geometry>
      <origin rpy="0 0 0" xyz="-0.0 0.0 0"/>
    </collision>
    <inertial>
      <mass value="0.005"/>
      <inertia ixx="1.9791666666666667e-07" ixy="0" ixz="0" iyy="1.9791666666666667e-07" iyz="0" izz="6.250000000000001e-08"/>
      <origin rpy="0 0 0" xyz="-0.0 0.0 0"/>
    </inertial>
  </link>

  <joint name="joint_tether_7" type="continuous">
    <origin rpy="0.0 0.0 0.0" xyz="0.0 0.0 0.02"/>
    <axis xyz="0 1 1"/>
    <parent link="link_tether_6"/>
    <child link="link_tether_7"/>
  </joint>

  <gazebo reference="tether_7">
    <material>Gazebo/Grey</material>
    <gravity>True</gravity>
    <selfCollide>True</selfCollide>
    <maxContacts>10</maxContacts>
    <dampingFactor>0.0</dampingFactor>
    <maxVel>0.0</maxVel>
    <minDepth>0.0</minDepth>
    <mu1>1.000000</mu1>
    <mu2>1.000000</mu2>
  </gazebo>

  <link name="link_tether_8">
    <visual>
      <geometry>
        <cylinder length="0.02" radius="0.005"/>
      </geometry>
      <origin rpy="0 0 0" xyz="-0.0 0.0 0"/>
      <material name="grey"/>
    </visual>
    <collision>
      <geometry>
        <cylinder length="0.02" radius="0.005"/>
      </geometry>
      <origin rpy="0 0 0" xyz="-0.0 0.0 0"/>
    </collision>
    <inertial>
      <mass value="0.005"/>
      <inertia ixx="1.9791666666666667e-07" ixy="0" ixz="0" iyy="1.9791666666666667e-07" iyz="0" izz="6.250000000000001e-08"/>
      <origin rpy="0 0 0" xyz="-0.0 0.0 0"/>
    </inertial>
  </link>

  <joint name="joint_tether_8" type="continuous">
    <origin rpy="0.0 0.0 0.0" xyz="0.0 0.0 0.02"/>
    <axis xyz="0 1 1"/>
    <parent link="link_tether_7"/>
    <child link="link_tether_8"/>
  </joint>

  <gazebo reference="tether_8">
    <material>Gazebo/Grey</material>
    <gravity>True</gravity>
    <selfCollide>True</selfCollide>
    <maxContacts>10</maxContacts>
    <dampingFactor>0.0</dampingFactor>
    <maxVel>0.0</maxVel>
    <minDepth>0.0</minDepth>
    <mu1>1.000000</mu1>
    <mu2>1.000000</mu2>
  </gazebo>

  <link name="link_tether_9">
    <visual>
      <geometry>
        <cylinder length="0.02" radius="0.005"/>
      </geometry>
      <origin rpy="0 0 0" xyz="-0.0 0.0 0"/>
      <material name="grey"/>
    </visual>
    <collision>
      <geometry>
        <cylinder length="0.02" radius="0.005"/>
      </geometry>
      <origin rpy="0 0 0" xyz="-0.0 0.0 0"/>
    </collision>
    <inertial>
      <mass value="0.005"/>
      <inertia ixx="1.9791666666666667e-07" ixy="0" ixz="0" iyy="1.9791666666666667e-07" iyz="0" izz="6.250000000000001e-08"/>
      <origin rpy="0 0 0" xyz="-0.0 0.0 0"/>
    </inertial>
  </link>

  <joint name="joint_tether_9" type="continuous">
    <origin rpy="0.0 0.0 0.0" xyz="0.0 0.0 0.02"/>
    <axis xyz="0 1 1"/>
    <parent link="link_tether_8"/>
    <child link="link_tether_9"/>
  </joint>

  <gazebo reference="tether_9">
    <material>Gazebo/Grey</material>
    <gravity>True</gravity>
    <selfCollide>True</selfCollide>
    <maxContacts>10</maxContacts>
    <dampingFactor>0.0</dampingFactor>
    <maxVel>0.0</maxVel>
    <minDepth>0.0</minDepth>
    <mu1>1.000000</mu1>
    <mu2>1.000000</mu2>
  </gazebo>

  <link name="link_tether_10">
    <visual>
      <geometry>
        <cylinder length="0.02" radius="0.005"/>
      </geometry>
      <origin rpy="0 0 0" xyz="-0.0 0.0 0"/>
      <material name="grey"/>
    </visual>
    <collision>
      <geometry>
        <cylinder length="0.02" radius="0.005"/>
      </geometry>
      <origin rpy="0 0 0" xyz="-0.0 0.0 0"/>
    </collision>
    <inertial>
      <mass value="0.005"/>
      <inertia ixx="1.9791666666666667e-07" ixy="0" ixz="0" iyy="1.9791666666666667e-07" iyz="0" izz="6.250000000000001e-08"/>
      <origin rpy="0 0 0" xyz="-0.0 0.0 0"/>
    </inertial>
  </link>

  <joint name="joint_tether_10" type="continuous">
    <origin rpy="0.0 0.0 0.0" xyz="0.0 0.0 0.02"/>
    <axis xyz="0 1 1"/>
    <parent link="link_tether_9"/>
    <child link="link_tether_10"/>
  </joint>

  <gazebo reference="tether_10">
    <material>Gazebo/Grey</material>
    <gravity>True</gravity>
    <selfCollide>True</selfCollide>
    <maxContacts>10</maxContacts>
    <dampingFactor>0.0</dampingFactor>
    <maxVel>0.0</maxVel>
    <minDepth>0.0</minDepth>
    <mu1>1.000000</mu1>
    <mu2>1.000000</mu2>
  </gazebo>

  <link name="link_tether_11">
    <visual>
      <geometry>
        <cylinder length="0.02" radius="0.005"/>
      </geometry>
      <origin rpy="0 0 0" xyz="-0.0 0.0 0"/>
      <material name="grey"/>
    </visual>
    <collision>
      <geometry>
        <cylinder length="0.02" radius="0.005"/>
      </geometry>
      <origin rpy="0 0 0" xyz="-0.0 0.0 0"/>
    </collision>
    <inertial>
      <mass value="0.005"/>
      <inertia ixx="1.9791666666666667e-07" ixy="0" ixz="0" iyy="1.9791666666666667e-07" iyz="0" izz="6.250000000000001e-08"/>
      <origin rpy="0 0 0" xyz="-0.0 0.0 0"/>
    </inertial>
  </link>

  <joint name="joint_tether_11" type="continuous">
    <origin rpy="0.0 0.0 0.0" xyz="0.0 0.0 0.02"/>
    <axis xyz="0 1 1"/>
    <parent link="link_tether_10"/>
    <child link="link_tether_11"/>
  </joint>

  <gazebo reference="tether_11">
    <material>Gazebo/Grey</material>
    <gravity>True</gravity>
    <selfCollide>True</selfCollide>
    <maxContacts>10</maxContacts>
    <dampingFactor>0.0</dampingFactor>
    <maxVel>0.0</maxVel>
    <minDepth>0.0</minDepth>
    <mu1>1.000000</mu1>
    <mu2>1.000000</mu2>
  </gazebo>

  <link name="link_tether_12">
    <visual>
      <geometry>
        <cylinder length="0.02" radius="0.005"/>
      </geometry>
      <origin rpy="0 0 0" xyz="-0.0 0.0 0"/>
      <material name="grey"/>
    </visual>
    <collision>
      <geometry>
        <cylinder length="0.02" radius="0.005"/>
      </geometry>
      <origin rpy="0 0 0" xyz="-0.0 0.0 0"/>
    </collision>
    <inertial>
      <mass value="0.005"/>
      <inertia ixx="1.9791666666666667e-07" ixy="0" ixz="0" iyy="1.9791666666666667e-07" iyz="0" izz="6.250000000000001e-08"/>
      <origin rpy="0 0 0" xyz="-0.0 0.0 0"/>
    </inertial>
  </link>

  <joint name="joint_tether_12" type="continuous">
    <origin rpy="0.0 0.0 0.0" xyz="0.0 0.0 0.02"/>
    <axis xyz="0 1 1"/>
    <parent link="link_tether_11"/>
    <child link="link_tether_12"/>
  </joint>

  <gazebo reference="tether_12">
    <material>Gazebo/Grey</material>
    <gravity>True</gravity>
    <selfCollide>True</selfCollide>
    <maxContacts>10</maxContacts>
    <dampingFactor>0.0</dampingFactor>
    <maxVel>0.0</maxVel>
    <minDepth>0.0</minDepth>
    <mu1>1.000000</mu1>
    <mu2>1.000000</mu2>
  </gazebo>

  <link name="link_tether_13">
    <visual>
      <geometry>
        <cylinder length="0.02" radius="0.005"/>
      </geometry>
      <origin rpy="0 0 0" xyz="-0.0 0.0 0"/>
      <material name="grey"/>
    </visual>
    <collision>
      <geometry>
        <cylinder length="0.02" radius="0.005"/>
      </geometry>
      <origin rpy="0 0 0" xyz="-0.0 0.0 0"/>
    </collision>
    <inertial>
      <mass value="0.005"/>
      <inertia ixx="1.9791666666666667e-07" ixy="0" ixz="0" iyy="1.9791666666666667e-07" iyz="0" izz="6.250000000000001e-08"/>
      <origin rpy="0 0 0" xyz="-0.0 0.0 0"/>
    </inertial>
  </link>

  <joint name="joint_tether_13" type="continuous">
    <origin rpy="0.0 0.0 0.0" xyz="0.0 0.0 0.02"/>
    <axis xyz="0 1 1"/>
    <parent link="link_tether_12"/>
    <child link="link_tether_13"/>
  </joint>

  <gazebo reference="tether_13">
    <material>Gazebo/Grey</material>
    <gravity>True</gravity>
    <selfCollide>True</selfCollide>
    <maxContacts>10</maxContacts>
    <dampingFactor>0.0</dampingFactor>
    <maxVel>0.0</maxVel>
    <minDepth>0.0</minDepth>
    <mu1>1.000000</mu1>
    <mu2>1.000000</mu2>
  </gazebo>

  <link name="link_tether_14">
    <visual>
      <geometry>
        <cylinder length="0.02" radius="0.005"/>
      </geometry>
      <origin rpy="0 0 0" xyz="-0.0 0.0 0"/>
      <material name="grey"/>
    </visual>
    <collision>
      <geometry>
        <cylinder length="0.02" radius="0.005"/>
      </geometry>
      <origin rpy="0 0 0" xyz="-0.0 0.0 0"/>
    </collision>
    <inertial>
      <mass value="0.005"/>
      <inertia ixx="1.9791666666666667e-07" ixy="0" ixz="0" iyy="1.9791666666666667e-07" iyz="0" izz="6.250000000000001e-08"/>
      <origin rpy="0 0 0" xyz="-0.0 0.0 0"/>
    </inertial>
  </link>

  <joint name="joint_tether_14" type="continuous">
    <origin rpy="0.0 0.0 0.0" xyz="0.0 0.0 0.02"/>
    <axis xyz="0 1 1"/>
    <parent link="link_tether_13"/>
    <child link="link_tether_14"/>
  </joint>

  <gazebo reference="tether_14">
    <material>Gazebo/Grey</material>
    <gravity>True</gravity>
    <selfCollide>True</selfCollide>
    <maxContacts>10</maxContacts>
    <dampingFactor>0.0</dampingFactor>
    <maxVel>0.0</maxVel>
    <minDepth>0.0</minDepth>
    <mu1>1.000000</mu1>
    <mu2>1.000000</mu2>
  </gazebo>

  <link name="link_tether_15">
    <visual>
      <geometry>
        <cylinder length="0.02" radius="0.005"/>
      </geometry>
      <origin rpy="0 0 0" xyz="-0.0 0.0 0"/>
      <material name="grey"/>
    </visual>
    <collision>
      <geometry>
        <cylinder length="0.02" radius="0.005"/>
      </geometry>
      <origin rpy="0 0 0" xyz="-0.0 0.0 0"/>
    </collision>
    <inertial>
      <mass value="0.005"/>
      <inertia ixx="1.9791666666666667e-07" ixy="0" ixz="0" iyy="1.9791666666666667e-07" iyz="0" izz="6.250000000000001e-08"/>
      <origin rpy="0 0 0" xyz="-0.0 0.0 0"/>
    </inertial>
  </link>

  <joint name="joint_tether_15" type="continuous">
    <origin rpy="0.0 0.0 0.0" xyz="0.0 0.0 0.02"/>
    <axis xyz="0 1 1"/>
    <parent link="link_tether_14"/>
    <child link="link_tether_15"/>
  </joint>

  <gazebo reference="tether_15">
    <material>Gazebo/Grey</material>
    <gravity>True</gravity>
    <selfCollide>True</selfCollide>
    <maxContacts>10</maxContacts>
    <dampingFactor>0.0</dampingFactor>
    <maxVel>0.0</maxVel>
    <minDepth>0.0</minDepth>
    <mu1>1.000000</mu1>
    <mu2>1.000000</mu2>
  </gazebo>

  <link name="link_tether_16">
    <visual>
      <geometry>
        <cylinder length="0.02" radius="0.005"/>
      </geometry>
      <origin rpy="0 0 0" xyz="-0.0 0.0 0"/>
      <material name="grey"/>
    </visual>
    <collision>
      <geometry>
        <cylinder length="0.02" radius="0.005"/>
      </geometry>
      <origin rpy="0 0 0" xyz="-0.0 0.0 0"/>
    </collision>
    <inertial>
      <mass value="0.005"/>
      <inertia ixx="1.9791666666666667e-07" ixy="0" ixz="0" iyy="1.9791666666666667e-07" iyz="0" izz="6.250000000000001e-08"/>
      <origin rpy="0 0 0" xyz="-0.0 0.0 0"/>
    </inertial>
  </link>

  <joint name="joint_tether_16" type="continuous">
    <origin rpy="0.0 0.0 0.0" xyz="0.0 0.0 0.02"/>
    <axis xyz="0 1 1"/>
    <parent link="link_tether_15"/>
    <child link="link_tether_16"/>
  </joint>

  <gazebo reference="tether_16">
    <material>Gazebo/Grey</material>
    <gravity>True</gravity>
    <selfCollide>True</selfCollide>
    <maxContacts>10</maxContacts>
    <dampingFactor>0.0</dampingFactor>
    <maxVel>0.0</maxVel>
    <minDepth>0.0</minDepth>
    <mu1>1.000000</mu1>
    <mu2>1.000000</mu2>
  </gazebo>

  <link name="link_tether_17">
    <visual>
      <geometry>
        <cylinder length="0.02" radius="0.005"/>
      </geometry>
      <origin rpy="0 0 0" xyz="-0.0 0.0 0"/>
      <material name="grey"/>
    </visual>
    <collision>
      <geometry>
        <cylinder length="0.02" radius="0.005"/>
      </geometry>
      <origin rpy="0 0 0" xyz="-0.0 0.0 0"/>
    </collision>
    <inertial>
      <mass value="0.005"/>
      <inertia ixx="1.9791666666666667e-07" ixy="0" ixz="0" iyy="1.9791666666666667e-07" iyz="0" izz="6.250000000000001e-08"/>
      <origin rpy="0 0 0" xyz="-0.0 0.0 0"/>
    </inertial>
  </link>

  <joint name="joint_tether_17" type="continuous">
    <origin rpy="0.0 0.0 0.0" xyz="0.0 0.0 0.02"/>
    <axis xyz="0 1 1"/>
    <parent link="link_tether_16"/>
    <child link="link_tether_17"/>
  </joint>

  <gazebo reference="tether_17">
    <material>Gazebo/Grey</material>
    <gravity>True</gravity>
    <selfCollide>True</selfCollide>
    <maxContacts>10</maxContacts>
    <dampingFactor>0.0</dampingFactor>
    <maxVel>0.0</maxVel>
    <minDepth>0.0</minDepth>
    <mu1>1.000000</mu1>
    <mu2>1.000000</mu2>
  </gazebo>

  <link name="link_tether_18">
    <visual>
      <geometry>
        <cylinder length="0.02" radius="0.005"/>
      </geometry>
      <origin rpy="0 0 0" xyz="-0.0 0.0 0"/>
      <material name="grey"/>
    </visual>
    <collision>
      <geometry>
        <cylinder length="0.02" radius="0.005"/>
      </geometry>
      <origin rpy="0 0 0" xyz="-0.0 0.0 0"/>
    </collision>
    <inertial>
      <mass value="0.005"/>
      <inertia ixx="1.9791666666666667e-07" ixy="0" ixz="0" iyy="1.9791666666666667e-07" iyz="0" izz="6.250000000000001e-08"/>
      <origin rpy="0 0 0" xyz="-0.0 0.0 0"/>
    </inertial>
  </link>

  <joint name="joint_tether_18" type="continuous">
    <origin rpy="0.0 0.0 0.0" xyz="0.0 0.0 0.02"/>
    <axis xyz="0 1 1"/>
    <parent link="link_tether_17"/>
    <child link="link_tether_18"/>
  </joint>

  <gazebo reference="tether_18">
    <material>Gazebo/Grey</material>
    <gravity>True</gravity>
    <selfCollide>True</selfCollide>
    <maxContacts>10</maxContacts>
    <dampingFactor>0.0</dampingFactor>
    <maxVel>0.0</maxVel>
    <minDepth>0.0</minDepth>
    <mu1>1.000000</mu1>
    <mu2>1.000000</mu2>
  </gazebo>

  <link name="link_tether_19">
    <visual>
      <geometry>
        <cylinder length="0.02" radius="0.005"/>
      </geometry>
      <origin rpy="0 0 0" xyz="-0.0 0.0 0"/>
      <material name="grey"/>
    </visual>
    <collision>
      <geometry>
        <cylinder length="0.02" radius="0.005"/>
      </geometry>
      <origin rpy="0 0 0" xyz="-0.0 0.0 0"/>
    </collision>
    <inertial>
      <mass value="0.005"/>
      <inertia ixx="1.9791666666666667e-07" ixy="0" ixz="0" iyy="1.9791666666666667e-07" iyz="0" izz="6.250000000000001e-08"/>
      <origin rpy="0 0 0" xyz="-0.0 0.0 0"/>
    </inertial>
  </link>

  <joint name="joint_tether_19" type="continuous">
    <origin rpy="0.0 0.0 0.0" xyz="0.0 0.0 0.02"/>
    <axis xyz="0 1 1"/>
    <parent link="link_tether_18"/>
    <child link="link_tether_19"/>
  </joint>

  <gazebo reference="tether_19">
    <material>Gazebo/Grey</material>
    <gravity>True</gravity>
    <selfCollide>True</selfCollide>
    <maxContacts>10</maxContacts>
    <dampingFactor>0.0</dampingFactor>
    <maxVel>0.0</maxVel>
    <minDepth>0.0</minDepth>
    <mu1>1.000000</mu1>
    <mu2>1.000000</mu2>
  </gazebo>

  <link name="link_tether_20">
    <visual>
      <geometry>
        <cylinder length="0.02" radius="0.005"/>
      </geometry>
      <origin rpy="0 0 0" xyz="-0.0 0.0 0"/>
      <material name="grey"/>
    </visual>
    <collision>
      <geometry>
        <cylinder length="0.02" radius="0.005"/>
      </geometry>
      <origin rpy="0 0 0" xyz="-0.0 0.0 0"/>
    </collision>
    <inertial>
      <mass value="0.005"/>
      <inertia ixx="1.9791666666666667e-07" ixy="0" ixz="0" iyy="1.9791666666666667e-07" iyz="0" izz="6.250000000000001e-08"/>
      <origin rpy="0 0 0" xyz="-0.0 0.0 0"/>
    </inertial>
  </link>

  <joint name="joint_tether_20" type="continuous">
    <origin rpy="0.0 0.0 0.0" xyz="0.0 0.0 0.02"/>
    <axis xyz="0 1 1"/>
    <parent link="link_tether_19"/>
    <child link="link_tether_20"/>
  </joint>

  <gazebo reference="tether_20">
    <material>Gazebo/Grey</material>
    <gravity>True</gravity>
    <selfCollide>True</selfCollide>
    <maxContacts>10</maxContacts>
    <dampingFactor>0.0</dampingFactor>
    <maxVel>0.0</maxVel>
    <minDepth>0.0</minDepth>
    <mu1>1.000000</mu1>
    <mu2>1.000000</mu2>
  </gazebo>

  <gazebo>
    <plugin filename="libgazebo_ros_modelate_tether.so" name="gazebo_ros_modelate_tether">
      <numLinkTether>20</numLinkTether>
      <nameLinkFrame>link_tether</nameLinkFrame>
    </plugin>
  </gazebo>