<material name="black">
    <color rgba="0.0 0.0 0.0 1.0"/>
  </material>
  <material name="blue">
    <color rgba="0.0 0.0 0.8 1.0"/>
  </material>
  <material name="grey">
    <color rgba="0.8 0.8 0.8 1"/>
  </material>
  <material name="gray">
    <color rgba="0.25 0.25 0.25 1"/>
  </material>
  <material name="orange">
    <color rgba="1.0 0.4235294117647059 0.0392156862745098 1.0"/>
  </material>
  <material name="yellow">
    <color rgba="1.0 1.0 0.0 1.0"/>
  </material>
  <material name="red">
    <color rgba="0.8 0.0 0.0 1.0"/>
  </material>
  <material name="white">
    <color rgba="1.0 1.0 1.0 1.0"/>
  </material>
  <!-- ros_control plugin -->
  <gazebo>
    <plugin filename="libgazebo_ros_control.so" name="gazebo_ros_control"/>
  </gazebo>

  <selfCollide>True</selfCollide>


  <gazebo>
    <plugin filename="libgazebo_ros_planar_move_optional_tf.so" name="robot_controller">
      <commandTopic>arco/idmind_motors/set_velocities</commandTopic>
      <odometryTopic>arco/idmind_motors/gazebo_odom</odometryTopic>
      <odometryFrame>arco/odom</odometryFrame>
      <odometryRate>20.0</odometryRate>
      <robotBaseFrame>arco/base_link</robotBaseFrame>
      <publishTf>true</publishTf>
    </plugin>
  </gazebo>


    <!-- .........................................................UGV STUFF.................................................................... -->

  <link name="arco/base_link">
     <origin rpy="0.0 0.0 0.0" xyz="0 0 0.0" />
  </link>

  <link name="arco/base_body">
    <visual>
      <geometry>
        <box size="0.66 0.38 0.14"/>
      </geometry>
      <material name="black"/>
      <origin rpy="0 0 0" xyz="0 0 0.07"/>
    </visual>
    <collision>
      <geometry>
        <box size="0.66 0.38 0.14"/>
      </geometry>
      <origin rpy="0 0 0" xyz="0 0 0.07"/>
    </collision>
    <inertial>
      <mass value="200.0"/>
      <inertia ixx="2.733333333333334" ixy="0.0" ixz="0.0" iyy="7.586666666666668" iyz="0.0" izz="9.666666666666668"/>
      <origin rpy="0 0 0" xyz="0 0 0.07"/>
    </inertial>
  </link>

   <joint name="base_to_footprint" type="fixed" >
        <parent link="arco/base_link" />
        <child link="arco/base_body" />
        <origin rpy="0.0 0.0 0.0" xyz="0 0 0.0" />
    </joint>

  <link name="arco/cover_link">
    <visual>
      <geometry>
        <box size="0.66 0.64 0.01"/>
      </geometry>
      <material name="grey"/>
      <origin rpy="0 0 0" xyz="0 0 0.07"/>
    </visual>
    <collision>
      <geometry>
        <box size="0.66 0.64 0.01"/>
      </geometry>
      <origin rpy="0 0 0" xyz="0 0 0.07"/>
    </collision>
    <inertial>
      <mass value="1.0"/>
      <inertia ixx="0.03630833333333333" ixy="0.0" ixz="0.0" iyy="0.03630833333333333" iyz="0.0" izz="0.0726"/>
      <origin rpy="0 0 0" xyz="0 0 0.005"/>
    </inertial>
  </link>

  <joint name="arco_base_to_footprint" type="fixed">
    <parent link="arco/base_link"/>
    <child link="arco/cover_link"/>
    <origin rpy="0.0 0.0 0.0" xyz="0 0 0.07"/>
  </joint>

  <link name="arco/uav_platform">
    <visual>
      <geometry>
        <box size="0.4 0.56 0.3"/>
      </geometry>
      <material name="blue">
        <color rgba="0 0 0.8 1"/>
      </material>
      <origin rpy="0 0 0" xyz="-0.10 0 0.07"/>
    </visual>
    <collision>
      <geometry>
        <box size="0.4 0.56 0.3"/>
      </geometry>
      <origin rpy="0 0 0" xyz="-0.10 0 0.07"/>
    </collision>
    <inertial>
      <mass value="4.0"/>
      <inertia ixx="0.08333333333333333" ixy="0.0" ixz="0.0" iyy="0.08333333333333333" iyz="0.0" izz="0.10666666666666669"/>
      <origin rpy="0 0 0" xyz="-0.10 0 0.15"/>
    </inertial>
  </link>

  <joint name="arco_platform_for_uav" type="fixed">
    <parent link="arco/cover_link"/>
    <child link="arco/uav_platform"/>
    <origin rpy="0.0 0.0 0.0" xyz="0 0 0.15"/>
  </joint>

  <link name="arco/front_left">
    <visual>
      <geometry>
        <mesh filename="package://marsupial_description/meshes/mecanum/mecanum_wheel_left.STL" scale="0.002 0.002 0.002"/>
      </geometry>
      <origin rpy="0 0 0" xyz="0 0 0"/>
      <material name="grey"/>
    </visual>
    <collision>
      <geometry>
        <cylinder length="0.07" radius="0.1015"/>
      </geometry>
      <origin rpy="1.57 0 0" xyz="0 0 0"/>
    </collision>
    <inertial>
      <mass value="0.5"/>
      <inertia ixx="0.0014919479166666666" ixy="0" ixz="0" iyy="0.0014919479166666666" iyz="0" izz="0.0025755625"/>
      <origin rpy="1.57 0 0" xyz="0 0 0"/>
    </inertial>
  </link>

  <joint name="arco_base_to_front_left" type="continuous">
    <axis xyz="0 1 0"/>
    <limit effort="1000" velocity="75.0"/>
    <parent link="arco/base_link"/>
    <child link="arco/front_left"/>
    <joint_properties damping="30" friction="110"/>
    <origin rpy="0.0 0.0 0.0" xyz="0.2795 -0.24 0.0"/>
  </joint>

  <gazebo reference="arco/front_left">
    <material>Gazebo/Orange</material>
    <gravity>true</gravity>
    <selfCollide>false</selfCollide>
    <maxContacts>10</maxContacts>
    <dampingFactor>0.0</dampingFactor>
    <maxVel>0.0</maxVel>
    <minDepth>0.0</minDepth>
    <mu1>1.000000</mu1>
    <mu2>1.000000</mu2>
  </gazebo>

  <link name="arco/front_right">
    <visual>
      <geometry>
        <mesh filename="package://marsupial_description/meshes/mecanum/mecanum_wheel_right.STL" scale="0.002 0.002 0.002"/>
      </geometry>
      <origin rpy="0 0 0" xyz="0 0 0"/>
      <material name="grey"/>
    </visual>
    <collision>
      <geometry>
        <cylinder length="0.07" radius="0.1015"/>
      </geometry>
      <origin rpy="1.57 0 0" xyz="0 0 0"/>
    </collision>
    <inertial>
      <mass value="0.5"/>
      <inertia ixx="0.0014919479166666666" ixy="0" ixz="0" iyy="0.0014919479166666666" iyz="0" izz="0.0025755625"/>
      <origin rpy="1.57 0 0" xyz="0 0 0"/>
    </inertial>
  </link>

  <joint name="arco_base_to_front_right" type="continuous">
    <axis xyz="0 1 0"/>
    <limit effort="1000" velocity="75.0"/>
    <parent link="arco/base_link"/>
    <child link="arco/front_right"/>
    <joint_properties damping="30" friction="110"/>
    <origin rpy="0.0 0.0 0.0" xyz="0.2795 0.24 0.0"/>
  </joint>

  <gazebo reference="arco/front_right">
    <material>Gazebo/Orange</material>
    <gravity>true</gravity>
    <selfCollide>false</selfCollide>
    <maxContacts>10</maxContacts>
    <dampingFactor>0.0</dampingFactor>
    <maxVel>0.0</maxVel>
    <minDepth>0.0</minDepth>
    <mu1>1.000000</mu1>
    <mu2>1.000000</mu2>
  </gazebo>
  
  <link name="arco/rear_left">
    <visual>
      <geometry>
        <mesh filename="package://marsupial_description/meshes/mecanum/mecanum_wheel_left.STL" scale="0.002 0.002 0.002"/>
      </geometry>
      <origin rpy="0 0 0" xyz="0 0 0"/>
      <material name="grey"/>
    </visual>
    <collision>
      <geometry>
        <cylinder length="0.07" radius="0.1015"/>
      </geometry>
      <origin rpy="1.57 0 0" xyz="0 0 0"/>
    </collision>
    <inertial>
      <mass value="0.5"/>
      <inertia ixx="0.0014919479166666666" ixy="0" ixz="0" iyy="0.0014919479166666666" iyz="0" izz="0.0025755625"/>
      <origin rpy="1.57 0 0" xyz="0 0 0"/>
    </inertial>
  </link>
 
  <joint name="arco_base_to_rear_left" type="continuous">
    <axis xyz="0 1 0"/>
    <limit effort="1000" velocity="75.0"/>
    <parent link="arco/base_link"/>
    <child link="arco/rear_left"/>
    <joint_properties damping="30" friction="110"/>
    <origin rpy="0.0 0.0 0.0" xyz="-0.2795 -0.24 0.0"/>
  </joint>
  
  <gazebo reference="arco/rear_left">
    <material>Gazebo/Orange</material>
    <gravity>true</gravity>
    <selfCollide>false</selfCollide>
    <maxContacts>10</maxContacts>
    <dampingFactor>0.0</dampingFactor>
    <maxVel>0.0</maxVel>
    <minDepth>0.0</minDepth>
    <mu1>1.000000</mu1>
    <mu2>1.000000</mu2>
  </gazebo>

  <link name="arco/rear_right">
    <visual>
      <geometry>
        <mesh filename="package://marsupial_description/meshes/mecanum/mecanum_wheel_right.STL" scale="0.002 0.002 0.002"/>
      </geometry>
      <origin rpy="0 0 0" xyz="0 0 0"/>
      <material name="grey"/>
    </visual>
    <collision>
      <geometry>
        <cylinder length="0.07" radius="0.1015"/>
      </geometry>
      <origin rpy="1.57 0 0" xyz="0 0 0"/>
    </collision>
    <inertial>
      <mass value="0.5"/>
      <inertia ixx="0.0014919479166666666" ixy="0" ixz="0" iyy="0.0014919479166666666" iyz="0" izz="0.0025755625"/>
      <origin rpy="1.57 0 0" xyz="0 0 0"/>
    </inertial>
  </link>

  <joint name="arco_base_to_rear_right" type="continuous">
    <axis xyz="0 1 0"/>
    <limit effort="1000" velocity="75.0"/>
    <parent link="arco/base_link"/>
    <child link="arco/rear_right"/>
    <joint_properties damping="30" friction="110"/>
    <origin rpy="0.0 0.0 0.0" xyz="-0.2795 0.24 0.0"/>
  </joint>

  <gazebo reference="arco/rear_right">
    <material>Gazebo/Orange</material>
    <gravity>true</gravity>
    <selfCollide>false</selfCollide>
    <maxContacts>10</maxContacts>
    <dampingFactor>0.0</dampingFactor>
    <maxVel>0.0</maxVel>
    <minDepth>0.0</minDepth>
    <mu1>1.000000</mu1>
    <mu2>1.000000</mu2>
  </gazebo>

  <link name="arco/imu">
    <visual>
      <geometry>
        <mesh filename="package://marsupial_description/meshes/razor_imu/razor_imu.stl" scale="0.001 0.001 0.001"/>
      </geometry>
      <material name="red"/>
      <origin rpy="0 0 0" xyz="0 0 0"/>
    </visual>
    <collision>
      <geometry>
        <box size="0.031 0.031 0.01"/>
      </geometry>
      <origin rpy="0 0 0" xyz="0 0 0"/>
    </collision>
    <inertial>
      <mass value="0.01"/>
      <inertia ixx="8.841666666666666e-07" ixy="0.0" ixz="0.0" iyy="8.841666666666666e-07" iyz="0.0" izz="1.6016666666666666e-06"/>
      <origin rpy="0 0 0" xyz="0 0 0"/>
    </inertial>
  </link>

  <joint name="arco_base_to_imu" type="fixed">
    <parent link="arco/base_link"/>
    <child link="arco/imu"/>
    <origin rpy="0 0 0" xyz="0.12 0.0 0.1428"/>
  </joint>

  <gazebo reference="imu">
    <material>Gazebo/Red</material>
    <gravity>true</gravity>
    <sensor name="imu_sensor" type="imu">
      <always_on>true</always_on>
      <update_rate>50</update_rate>
      <visualize>true</visualize>
      <topic>__default_topic__</topic>
      <plugin filename="libgazebo_ros_imu_sensor.so" name="imu_plugin">
        <topicName>arco/imu</topicName>
        <bodyName>arco/imu</bodyName>
        <updateRateHZ>20.0</updateRateHZ>
        <gaussianNoise>0.0</gaussianNoise>
        <xyzOffset>0 0 0</xyzOffset>
        <rpyOffset>0 0 0</rpyOffset>
        <frameName>arco/imu</frameName>
      </plugin>
      <pose>0 0 0 0 0 0</pose>
    </sensor>
  </gazebo>

  <joint name="os1_sensor_base_mount_joint" type="fixed">
    <origin rpy="0 0 0" xyz="0.2795 0.0 0.14140000000000003"/>
    <parent link="arco/base_link"/>
    <child link="arco/os1_sensor_base_link"/>
  </joint>

  <link name="arco/os1_sensor_base_link">
    <inertial>
      <mass value="0.83"/>
      <origin xyz="0 0 0.03585"/>
      <inertia ixx="0.000908059425" ixy="0" ixz="0" iyy="0.000908059425" iyz="0" izz="0.0011049624"/>
    </inertial>
    <visual>
      <geometry>
        <mesh filename="package://marsupial_description/meshes/VLP16/VLP16_base_1.dae"/>
      </geometry>
    </visual>
    <visual>
      <geometry>
        <mesh filename="package://marsupial_description/meshes/VLP16/VLP16_base_2.dae"/>
      </geometry>
    </visual>
    <collision>
      <origin rpy="0 0 0" xyz="0 0 0.03585"/>
      <geometry>
        <cylinder length="0.0717" radius="0.0516"/>
      </geometry>
    </collision>
  </link>

  <joint name="arco_os1_sensor_base_scan_joint" type="fixed">
    <origin rpy="0 0 0" xyz="0 0 0.0377"/>
    <parent link="arco/os1_sensor_base_link"/>
    <child link="arco/os1_sensor"/>
  </joint>

  <link name="arco/os1_sensor">
    <inertial>
      <mass value="0.01"/>
      <origin xyz="0 0 0"/>
      <inertia ixx="1e-7" ixy="0" ixz="0" iyy="1e-7" iyz="0" izz="1e-7"/>
    </inertial>
    <visual>
      <origin xyz="0 0 -0.0377"/>
      <geometry>
        <mesh filename="package://marsupial_description/meshes/VLP16/VLP16_scan.dae"/>
      </geometry>
    </visual>
  </link>

  <!-- Gazebo requires the velodyne_gazebo_plugins package -->
  <gazebo reference="os1_sensor">
    <sensor name="os1_sensor-VLP16" type="ray">
      <pose>0 0 0 0 0 0</pose>
      <visualize>false</visualize>
      <update_rate>10</update_rate>
      <ray>
        <scan>
          <horizontal>
            <samples>1875</samples>
            <resolution>1</resolution>
            <min_angle>-3.141592653589793</min_angle>
            <max_angle>3.141592653589793</max_angle>
          </horizontal>
          <vertical>
            <samples>16</samples>
            <resolution>1</resolution>
            <min_angle>-0.2617993877991494</min_angle>
            <max_angle> 0.2617993877991494</max_angle>
          </vertical>
        </scan>
        <range>
          <min>0.3</min>
          <max>131.0</max>
          <resolution>0.001</resolution>
        </range>
        <noise>
          <type>gaussian</type>
          <mean>0.0</mean>
          <stddev>0.0</stddev>
        </noise>
      </ray>
      <plugin filename="libgazebo_ros_velodyne_laser.so" name="gazebo_ros_laser_arco">
        <topicName>arco/os1_cloud_node/points</topicName>
        <frameName>arco/os1_sensor</frameName>
        <organize_cloud>False</organize_cloud>
        <min_range>0.9</min_range>
        <max_range>130.0</max_range>
        <gaussianNoise>0.008</gaussianNoise>
      </plugin>
    </sensor>
  </gazebo>
  