<?xml version="1.0" ?>
<!-- =================================================================================== -->
<!-- |    This document was autogenerated by xacro from arco.xacro                     | -->
<!-- |    EDITING THIS FILE BY HAND IS NOT RECOMMENDED                                 | -->
<!-- =================================================================================== -->
<robot name="marsupial">

<material name="black">
    <color rgba="0.0 0.0 0.0 1.0"/>
  </material>
  <material name="blue">
    <color rgba="0.0 0.0 0.8 1.0"/>
  </material>
  <material name="grey">
    <color rgba="0.8 0.8 0.8 1"/>
  </material>
  <material name="gray">
    <color rgba="0.25 0.25 0.25 1"/>
  </material>
  <material name="orange">
    <color rgba="1.0 0.4235294117647059 0.0392156862745098 1.0"/>
  </material>
  <material name="yellow">
    <color rgba="1.0 1.0 0.0 1.0"/>
  </material>
  <material name="red">
    <color rgba="0.8 0.0 0.0 1.0"/>
  </material>
  <material name="white">
    <color rgba="1.0 1.0 1.0 1.0"/>
  </material>
  <!-- ros_control plugin -->
  <gazebo>
    <plugin filename="libgazebo_ros_control.so" name="gazebo_ros_control"/>
  </gazebo>

  <selfCollide>False</selfCollide>


  <gazebo>
    <plugin filename="libgazebo_ros_planar_move_optional_tf.so" name="robot_controller">
      <commandTopic>arco/idmind_motors/set_velocities</commandTopic>
      <odometryTopic>arco/idmind_motors/gazebo_odom</odometryTopic>
      <odometryFrame>arco/odom</odometryFrame>
      <odometryRate>20.0</odometryRate>
      <robotBaseFrame>arco/base_link</robotBaseFrame>
      <publishTf>true</publishTf>
    </plugin>
  </gazebo>


    <!-- .........................................................UGV STUFF.................................................................... -->

  <link name="arco/base_link">
     <origin rpy="0.0 0.0 0.0" xyz="0 0 0.0" />
  </link>

  <link name="arco/base_body">
    <visual>
      <geometry>
        <box size="0.66 0.38 0.14"/>
      </geometry>
      <material name="black"/>
      <origin rpy="0 0 0" xyz="0 0 0.07"/>
    </visual>
    <collision>
      <geometry>
        <box size="0.66 0.38 0.14"/>
      </geometry>
      <origin rpy="0 0 0" xyz="0 0 0.07"/>
    </collision>
    <inertial>
      <mass value="200.0"/>
      <inertia ixx="2.733333333333334" ixy="0.0" ixz="0.0" iyy="7.586666666666668" iyz="0.0" izz="9.666666666666668"/>
      <origin rpy="0 0 0" xyz="0 0 0.07"/>
    </inertial>
  </link>

   <joint name="base_to_footprint" type="fixed" >
        <parent link="arco/base_link" />
        <child link="arco/base_body" />
        <origin rpy="0.0 0.0 0.0" xyz="0 0 0.0" />
    </joint>

  <link name="arco/cover_link">
    <visual>
      <geometry>
        <box size="0.66 0.64 0.01"/>
      </geometry>
      <material name="grey"/>
      <origin rpy="0 0 0" xyz="0 0 0.07"/>
    </visual>
    <collision>
      <geometry>
        <box size="0.66 0.64 0.01"/>
      </geometry>
      <origin rpy="0 0 0" xyz="0 0 0.07"/>
    </collision>
    <inertial>
      <mass value="1.0"/>
      <inertia ixx="0.03630833333333333" ixy="0.0" ixz="0.0" iyy="0.03630833333333333" iyz="0.0" izz="0.0726"/>
      <origin rpy="0 0 0" xyz="0 0 0.005"/>
    </inertial>
  </link>

  <joint name="arco_base_to_footprint" type="fixed">
    <parent link="arco/base_link"/>
    <child link="arco/cover_link"/>
    <origin rpy="0.0 0.0 0.0" xyz="0 0 0.07"/>
  </joint>

  <link name="arco/uav_platform">
    <visual>
      <geometry>
        <box size="0.4 0.56 0.3"/>
      </geometry>
      <material name="blue">
        <color rgba="0 0 0.8 1"/>
      </material>
      <origin rpy="0 0 0" xyz="-0.10 0 0.07"/>
    </visual>
    <collision>
      <geometry>
        <box size="0.4 0.56 0.3"/>
      </geometry>
      <origin rpy="0 0 0" xyz="-0.10 0 0.07"/>
    </collision>
    <inertial>
      <mass value="4.0"/>
      <inertia ixx="0.08333333333333333" ixy="0.0" ixz="0.0" iyy="0.08333333333333333" iyz="0.0" izz="0.10666666666666669"/>
      <origin rpy="0 0 0" xyz="-0.10 0 0.15"/>
    </inertial>
  </link>

  <joint name="arco_platform_for_uav" type="fixed">
    <parent link="arco/cover_link"/>
    <child link="arco/uav_platform"/>
    <origin rpy="0.0 0.0 0.0" xyz="0 0 0.15"/>
  </joint>

  <link name="arco/front_left">
    <visual>
      <geometry>
        <mesh filename="package://marsupial_description/meshes/mecanum/mecanum_wheel_left.STL" scale="0.002 0.002 0.002"/>
      </geometry>
      <origin rpy="0 0 0" xyz="0 0 0"/>
      <material name="grey"/>
    </visual>
    <collision>
      <geometry>
        <cylinder length="0.07" radius="0.1015"/>
      </geometry>
      <origin rpy="1.57 0 0" xyz="0 0 0"/>
    </collision>
    <inertial>
      <mass value="0.5"/>
      <inertia ixx="0.0014919479166666666" ixy="0" ixz="0" iyy="0.0014919479166666666" iyz="0" izz="0.0025755625"/>
      <origin rpy="1.57 0 0" xyz="0 0 0"/>
    </inertial>
  </link>

  <joint name="arco_base_to_front_left" type="continuous">
    <axis xyz="0 1 0"/>
    <limit effort="1000" velocity="75.0"/>
    <parent link="arco/base_link"/>
    <child link="arco/front_left"/>
    <joint_properties damping="30" friction="110"/>
    <origin rpy="0.0 0.0 0.0" xyz="0.2795 -0.24 0.0"/>
  </joint>

  <gazebo reference="arco/front_left">
    <material>Gazebo/Orange</material>
    <gravity>true</gravity>
    <selfCollide>false</selfCollide>
    <maxContacts>10</maxContacts>
    <dampingFactor>0.0</dampingFactor>
    <maxVel>0.0</maxVel>
    <minDepth>0.0</minDepth>
    <mu1>1.000000</mu1>
    <mu2>1.000000</mu2>
  </gazebo>

  <link name="arco/front_right">
    <visual>
      <geometry>
        <mesh filename="package://marsupial_description/meshes/mecanum/mecanum_wheel_right.STL" scale="0.002 0.002 0.002"/>
      </geometry>
      <origin rpy="0 0 0" xyz="0 0 0"/>
      <material name="grey"/>
    </visual>
    <collision>
      <geometry>
        <cylinder length="0.07" radius="0.1015"/>
      </geometry>
      <origin rpy="1.57 0 0" xyz="0 0 0"/>
    </collision>
    <inertial>
      <mass value="0.5"/>
      <inertia ixx="0.0014919479166666666" ixy="0" ixz="0" iyy="0.0014919479166666666" iyz="0" izz="0.0025755625"/>
      <origin rpy="1.57 0 0" xyz="0 0 0"/>
    </inertial>
  </link>

  <joint name="arco_base_to_front_right" type="continuous">
    <axis xyz="0 1 0"/>
    <limit effort="1000" velocity="75.0"/>
    <parent link="arco/base_link"/>
    <child link="arco/front_right"/>
    <joint_properties damping="30" friction="110"/>
    <origin rpy="0.0 0.0 0.0" xyz="0.2795 0.24 0.0"/>
  </joint>

  <gazebo reference="arco/front_right">
    <material>Gazebo/Orange</material>
    <gravity>true</gravity>
    <selfCollide>false</selfCollide>
    <maxContacts>10</maxContacts>
    <dampingFactor>0.0</dampingFactor>
    <maxVel>0.0</maxVel>
    <minDepth>0.0</minDepth>
    <mu1>1.000000</mu1>
    <mu2>1.000000</mu2>
  </gazebo>
  
  <link name="arco/rear_left">
    <visual>
      <geometry>
        <mesh filename="package://marsupial_description/meshes/mecanum/mecanum_wheel_left.STL" scale="0.002 0.002 0.002"/>
      </geometry>
      <origin rpy="0 0 0" xyz="0 0 0"/>
      <material name="grey"/>
    </visual>
    <collision>
      <geometry>
        <cylinder length="0.07" radius="0.1015"/>
      </geometry>
      <origin rpy="1.57 0 0" xyz="0 0 0"/>
    </collision>
    <inertial>
      <mass value="0.5"/>
      <inertia ixx="0.0014919479166666666" ixy="0" ixz="0" iyy="0.0014919479166666666" iyz="0" izz="0.0025755625"/>
      <origin rpy="1.57 0 0" xyz="0 0 0"/>
    </inertial>
  </link>
 
  <joint name="arco_base_to_rear_left" type="continuous">
    <axis xyz="0 1 0"/>
    <limit effort="1000" velocity="75.0"/>
    <parent link="arco/base_link"/>
    <child link="arco/rear_left"/>
    <joint_properties damping="30" friction="110"/>
    <origin rpy="0.0 0.0 0.0" xyz="-0.2795 -0.24 0.0"/>
  </joint>
  
  <gazebo reference="arco/rear_left">
    <material>Gazebo/Orange</material>
    <gravity>true</gravity>
    <selfCollide>false</selfCollide>
    <maxContacts>10</maxContacts>
    <dampingFactor>0.0</dampingFactor>
    <maxVel>0.0</maxVel>
    <minDepth>0.0</minDepth>
    <mu1>1.000000</mu1>
    <mu2>1.000000</mu2>
  </gazebo>

  <link name="arco/rear_right">
    <visual>
      <geometry>
        <mesh filename="package://marsupial_description/meshes/mecanum/mecanum_wheel_right.STL" scale="0.002 0.002 0.002"/>
      </geometry>
      <origin rpy="0 0 0" xyz="0 0 0"/>
      <material name="grey"/>
    </visual>
    <collision>
      <geometry>
        <cylinder length="0.07" radius="0.1015"/>
      </geometry>
      <origin rpy="1.57 0 0" xyz="0 0 0"/>
    </collision>
    <inertial>
      <mass value="0.5"/>
      <inertia ixx="0.0014919479166666666" ixy="0" ixz="0" iyy="0.0014919479166666666" iyz="0" izz="0.0025755625"/>
      <origin rpy="1.57 0 0" xyz="0 0 0"/>
    </inertial>
  </link>

  <joint name="arco_base_to_rear_right" type="continuous">
    <axis xyz="0 1 0"/>
    <limit effort="1000" velocity="75.0"/>
    <parent link="arco/base_link"/>
    <child link="arco/rear_right"/>
    <joint_properties damping="30" friction="110"/>
    <origin rpy="0.0 0.0 0.0" xyz="-0.2795 0.24 0.0"/>
  </joint>

  <gazebo reference="arco/rear_right">
    <material>Gazebo/Orange</material>
    <gravity>true</gravity>
    <selfCollide>false</selfCollide>
    <maxContacts>10</maxContacts>
    <dampingFactor>0.0</dampingFactor>
    <maxVel>0.0</maxVel>
    <minDepth>0.0</minDepth>
    <mu1>1.000000</mu1>
    <mu2>1.000000</mu2>
  </gazebo>

  <link name="arco/imu">
    <visual>
      <geometry>
        <mesh filename="package://marsupial_description/meshes/razor_imu/razor_imu.stl" scale="0.001 0.001 0.001"/>
      </geometry>
      <material name="red"/>
      <origin rpy="0 0 0" xyz="0 0 0"/>
    </visual>
    <collision>
      <geometry>
        <box size="0.031 0.031 0.01"/>
      </geometry>
      <origin rpy="0 0 0" xyz="0 0 0"/>
    </collision>
    <inertial>
      <mass value="0.01"/>
      <inertia ixx="8.841666666666666e-07" ixy="0.0" ixz="0.0" iyy="8.841666666666666e-07" iyz="0.0" izz="1.6016666666666666e-06"/>
      <origin rpy="0 0 0" xyz="0 0 0"/>
    </inertial>
  </link>

  <joint name="arco_base_to_imu" type="fixed">
    <parent link="arco/base_link"/>
    <child link="arco/imu"/>
    <origin rpy="0 0 0" xyz="0.12 0.0 0.1428"/>
  </joint>

  <gazebo reference="imu">
    <material>Gazebo/Red</material>
    <gravity>true</gravity>
    <sensor name="imu_sensor" type="imu">
      <always_on>true</always_on>
      <update_rate>50</update_rate>
      <visualize>true</visualize>
      <topic>__default_topic__</topic>
      <plugin filename="libgazebo_ros_imu_sensor.so" name="imu_plugin">
        <topicName>arco/imu</topicName>
        <bodyName>arco/imu</bodyName>
        <updateRateHZ>20.0</updateRateHZ>
        <gaussianNoise>0.0</gaussianNoise>
        <xyzOffset>0 0 0</xyzOffset>
        <rpyOffset>0 0 0</rpyOffset>
        <frameName>arco/imu</frameName>
      </plugin>
      <pose>0 0 0 0 0 0</pose>
    </sensor>
  </gazebo>

  <joint name="os1_sensor_base_mount_joint" type="fixed">
    <origin rpy="0 0 0" xyz="0.2795 0.0 0.14140000000000003"/>
    <parent link="arco/base_link"/>
    <child link="arco/os1_sensor_base_link"/>
  </joint>

  <link name="arco/os1_sensor_base_link">
    <inertial>
      <mass value="0.83"/>
      <origin xyz="0 0 0.03585"/>
      <inertia ixx="0.000908059425" ixy="0" ixz="0" iyy="0.000908059425" iyz="0" izz="0.0011049624"/>
    </inertial>
    <visual>
      <geometry>
        <mesh filename="package://marsupial_description/meshes/VLP16/VLP16_base_1.dae"/>
      </geometry>
    </visual>
    <visual>
      <geometry>
        <mesh filename="package://marsupial_description/meshes/VLP16/VLP16_base_2.dae"/>
      </geometry>
    </visual>
    <collision>
      <origin rpy="0 0 0" xyz="0 0 0.03585"/>
      <geometry>
        <cylinder length="0.0717" radius="0.0516"/>
      </geometry>
    </collision>
  </link>

  <joint name="arco_os1_sensor_base_scan_joint" type="fixed">
    <origin rpy="0 0 0" xyz="0 0 0.0377"/>
    <parent link="arco/os1_sensor_base_link"/>
    <child link="arco/os1_sensor"/>
  </joint>

  <link name="arco/os1_sensor">
    <inertial>
      <mass value="0.01"/>
      <origin xyz="0 0 0"/>
      <inertia ixx="1e-7" ixy="0" ixz="0" iyy="1e-7" iyz="0" izz="1e-7"/>
    </inertial>
    <visual>
      <origin xyz="0 0 -0.0377"/>
      <geometry>
        <mesh filename="package://marsupial_description/meshes/VLP16/VLP16_scan.dae"/>
      </geometry>
    </visual>
  </link>

  <!-- Gazebo requires the velodyne_gazebo_plugins package -->
  <gazebo reference="os1_sensor">
    <sensor name="os1_sensor-VLP16" type="ray">
      <pose>0 0 0 0 0 0</pose>
      <visualize>false</visualize>
      <update_rate>10</update_rate>
      <ray>
        <scan>
          <horizontal>
            <samples>1875</samples>
            <resolution>1</resolution>
            <min_angle>-3.141592653589793</min_angle>
            <max_angle>3.141592653589793</max_angle>
          </horizontal>
          <vertical>
            <samples>16</samples>
            <resolution>1</resolution>
            <min_angle>-0.2617993877991494</min_angle>
            <max_angle> 0.2617993877991494</max_angle>
          </vertical>
        </scan>
        <range>
          <min>0.3</min>
          <max>131.0</max>
          <resolution>0.001</resolution>
        </range>
        <noise>
          <type>gaussian</type>
          <mean>0.0</mean>
          <stddev>0.0</stddev>
        </noise>
      </ray>
      <plugin filename="libgazebo_ros_velodyne_laser.so" name="gazebo_ros_laser_arco">
        <topicName>arco/os1_cloud_node/points</topicName>
        <frameName>arco/os1_sensor</frameName>
        <organize_cloud>False</organize_cloud>
        <min_range>0.9</min_range>
        <max_range>130.0</max_range>
        <gaussianNoise>0.008</gaussianNoise>
      </plugin>
    </sensor>
  </gazebo>
  
 <!-- .........................................................TETHER STUFF.................................................................... -->
 
   <link name="tether/link_1">
    <visual>
      <geometry>
        <cylinder length="0.02" radius="0.005"/>
      </geometry>
      <origin rpy="0 0 0" xyz="-0.0 0.0 0"/>
      <material name="Gazebo/Grey"/>
    </visual>
    <collision>
      <geometry>
        <cylinder length="0.02" radius="0.005"/>
      </geometry>
      <origin rpy="0 0 0" xyz="-0.0 0.0 0"/>
    </collision>
    <inertial>
      <mass value="0.001"/>
      <inertia ixx="1.9791666666666667e-07" ixy="0" ixz="0" iyy="1.9791666666666667e-07" iyz="0" izz="6.250000000000001e-08"/>
      <origin rpy="0 0 0" xyz="-0.0 0.0 0"/>
    </inertial>
  </link>
  <link name="tether/link_02">
    <visual>
      <geometry>
        <cylinder length="0.02" radius="0.005"/>
      </geometry>
      <origin rpy="0 0 0" xyz="-0.0 0.0 0"/>
      <material name="Gazebo/Grey"/>
    </visual>
    <collision>
      <geometry>
        <cylinder length="0.02" radius="0.005"/>
      </geometry>
      <origin rpy="0 0 0" xyz="-0.0 0.0 0"/>
    </collision>
    <inertial>
      <mass value="0.001"/>
      <inertia ixx="1.9791666666666667e-07" ixy="0" ixz="0" iyy="1.9791666666666667e-07" iyz="0" izz="6.250000000000001e-08"/>
      <origin rpy="0 0 0" xyz="-0.0 0.0 0"/>
    </inertial>
  </link>

  <joint name="joint_tether_2" type="continuous">
    <origin rpy="0.0 0.0 0.0" xyz="0.0 0.0 0.02"/>
    <axis xyz="0 1 1"/>
    <!-- TODO(ff): not currently set because it's not yet supported -->
    <!-- <limit effort="2000" velocity="${max_rot_velocity}" /> -->
    <parent link="tether/link_1"/>
    <child link="tether/link_02"/>
  </joint>

  <link name="tether/link_03">
    <visual>
      <geometry>
        <cylinder length="0.02" radius="0.005"/>
      </geometry>
      <origin rpy="0 0 0" xyz="-0.0 0.0 0"/>
      <material name="Gazebo/Grey"/>
    </visual>
    <collision>
      <geometry>
        <cylinder length="0.02" radius="0.005"/>
      </geometry>
      <origin rpy="0 0 0" xyz="-0.0 0.0 0"/>
    </collision>
    <inertial>
      <mass value="0.001"/>
      <inertia ixx="1.9791666666666667e-07" ixy="0" ixz="0" iyy="1.9791666666666667e-07" iyz="0" izz="6.250000000000001e-08"/>
      <origin rpy="0 0 0" xyz="-0.0 0.0 0"/>
    </inertial>
  </link>

  <joint name="joint_tether_3" type="continuous">
    <origin rpy="0.0 0.0 0.0" xyz="0.0 0.0 0.02"/>
    <axis xyz="0 1 1"/>
    <!-- TODO(ff): not currently set because it's not yet supported -->
    <!-- <limit effort="2000" velocity="${max_rot_velocity}" /> -->
    <parent link="tether/link_02"/>
    <child link="tether/link_03"/>
  </joint>

  <link name="tether/link_04">
    <visual>
      <geometry>
        <cylinder length="0.02" radius="0.005"/>
      </geometry>
      <origin rpy="0 0 0" xyz="-0.0 0.0 0"/>
      <material name="Gazebo/Grey"/>
    </visual>
    <collision>
      <geometry>
        <cylinder length="0.02" radius="0.005"/>
      </geometry>
      <origin rpy="0 0 0" xyz="-0.0 0.0 0"/>
    </collision>
    <inertial>
      <mass value="0.001"/>
      <inertia ixx="1.9791666666666667e-07" ixy="0" ixz="0" iyy="1.9791666666666667e-07" iyz="0" izz="6.250000000000001e-08"/>
      <origin rpy="0 0 0" xyz="-0.0 0.0 0"/>
    </inertial>
  </link>
  <joint name="joint_tether_4" type="continuous">
    <origin rpy="0.0 0.0 0.0" xyz="0.0 0.0 0.02"/>
    <axis xyz="0 1 1"/>
    <!-- TODO(ff): not currently set because it's not yet supported -->
    <!-- <limit effort="2000" velocity="${max_rot_velocity}" /> -->
    <parent link="tether/link_03"/>
    <child link="tether/link_04"/>
  </joint>
  <link name="tether/link_05">
    <visual>
      <geometry>
        <cylinder length="0.02" radius="0.005"/>
      </geometry>
      <origin rpy="0 0 0" xyz="-0.0 0.0 0"/>
      <material name="Gazebo/Grey"/>
    </visual>
    <collision>
      <geometry>
        <cylinder length="0.02" radius="0.005"/>
      </geometry>
      <origin rpy="0 0 0" xyz="-0.0 0.0 0"/>
    </collision>
    <inertial>
      <mass value="0.001"/>
      <inertia ixx="1.9791666666666667e-07" ixy="0" ixz="0" iyy="1.9791666666666667e-07" iyz="0" izz="6.250000000000001e-08"/>
      <origin rpy="0 0 0" xyz="-0.0 0.0 0"/>
    </inertial>
  </link>
  <joint name="joint_tether_5" type="continuous">
    <origin rpy="0.0 0.0 0.0" xyz="0.0 0.0 0.02"/>
    <axis xyz="0 1 1"/>
    <!-- TODO(ff): not currently set because it's not yet supported -->
    <!-- <limit effort="2000" velocity="${max_rot_velocity}" /> -->
    <parent link="tether/link_04"/>
    <child link="tether/link_05"/>
  </joint>
  
  <link name="tether/link_06">
    <visual>
      <geometry>
        <cylinder length="0.02" radius="0.005"/>
      </geometry>
      <origin rpy="0 0 0" xyz="-0.0 0.0 0"/>
      <material name="Gazebo/Grey"/>
    </visual>
    <collision>
      <geometry>
        <cylinder length="0.02" radius="0.005"/>
      </geometry>
      <origin rpy="0 0 0" xyz="-0.0 0.0 0"/>
    </collision>
    <inertial>
      <mass value="0.001"/>
      <inertia ixx="1.9791666666666667e-07" ixy="0" ixz="0" iyy="1.9791666666666667e-07" iyz="0" izz="6.250000000000001e-08"/>
      <origin rpy="0 0 0" xyz="-0.0 0.0 0"/>
    </inertial>
  </link>
  <joint name="joint_tether_6" type="continuous">
    <origin rpy="0.0 0.0 0.0" xyz="0.0 0.0 0.02"/>
    <axis xyz="0 1 1"/>
    <!-- TODO(ff): not currently set because it's not yet supported -->
    <!-- <limit effort="2000" velocity="${max_rot_velocity}" /> -->
    <parent link="tether/link_05"/>
    <child link="tether/link_06"/>
  </joint>
  <link name="tether/link_07">
    <visual>
      <geometry>
        <cylinder length="0.02" radius="0.005"/>
      </geometry>
      <origin rpy="0 0 0" xyz="-0.0 0.0 0"/>
      <material name="Gazebo/Grey"/>
    </visual>
    <collision>
      <geometry>
        <cylinder length="0.02" radius="0.005"/>
      </geometry>
      <origin rpy="0 0 0" xyz="-0.0 0.0 0"/>
    </collision>
    <inertial>
      <mass value="0.001"/>
      <inertia ixx="1.9791666666666667e-07" ixy="0" ixz="0" iyy="1.9791666666666667e-07" iyz="0" izz="6.250000000000001e-08"/>
      <origin rpy="0 0 0" xyz="-0.0 0.0 0"/>
    </inertial>
  </link>
  <joint name="joint_tether_7" type="continuous">
    <origin rpy="0.0 0.0 0.0" xyz="0.0 0.0 0.02"/>
    <axis xyz="0 1 1"/>
    <!-- TODO(ff): not currently set because it's not yet supported -->
    <!-- <limit effort="2000" velocity="${max_rot_velocity}" /> -->
    <parent link="tether/link_06"/>
    <child link="tether/link_07"/>
  </joint>
  <link name="tether/link_08">
    <visual>
      <geometry>
        <cylinder length="0.02" radius="0.005"/>
      </geometry>
      <origin rpy="0 0 0" xyz="-0.0 0.0 0"/>
      <material name="Gazebo/Grey"/>
    </visual>
    <collision>
      <geometry>
        <cylinder length="0.02" radius="0.005"/>
      </geometry>
      <origin rpy="0 0 0" xyz="-0.0 0.0 0"/>
    </collision>
    <inertial>
      <mass value="0.001"/>
      <inertia ixx="1.9791666666666667e-07" ixy="0" ixz="0" iyy="1.9791666666666667e-07" iyz="0" izz="6.250000000000001e-08"/>
      <origin rpy="0 0 0" xyz="-0.0 0.0 0"/>
    </inertial>
  </link>
  <joint name="joint_tether_8" type="continuous">
    <origin rpy="0.0 0.0 0.0" xyz="0.0 0.0 0.02"/>
    <axis xyz="0 1 1"/>
    <!-- TODO(ff): not currently set because it's not yet supported -->
    <!-- <limit effort="2000" velocity="${max_rot_velocity}" /> -->
    <parent link="tether/link_07"/>
    <child link="tether/link_08"/>
  </joint>
  <link name="tether/link_09">
    <visual>
      <geometry>
        <cylinder length="0.02" radius="0.005"/>
      </geometry>
      <origin rpy="0 0 0" xyz="-0.0 0.0 0"/>
      <material name="Gazebo/Grey"/>
    </visual>
    <collision>
      <geometry>
        <cylinder length="0.02" radius="0.005"/>
      </geometry>
      <origin rpy="0 0 0" xyz="-0.0 0.0 0"/>
    </collision>
    <inertial>
      <mass value="0.001"/>
      <inertia ixx="1.9791666666666667e-07" ixy="0" ixz="0" iyy="1.9791666666666667e-07" iyz="0" izz="6.250000000000001e-08"/>
      <origin rpy="0 0 0" xyz="-0.0 0.0 0"/>
    </inertial>
  </link>
  <joint name="joint_tether_9" type="continuous">
    <origin rpy="0.0 0.0 0.0" xyz="0.0 0.0 0.02"/>
    <axis xyz="0 1 1"/>
    <!-- TODO(ff): not currently set because it's not yet supported -->
    <!-- <limit effort="2000" velocity="${max_rot_velocity}" /> -->
    <parent link="tether/link_08"/>
    <child link="tether/link_09"/>
  </joint>
  <link name="tether/link_10">
    <visual>
      <geometry>
        <cylinder length="0.02" radius="0.005"/>
      </geometry>
      <origin rpy="0 0 0" xyz="-0.0 0.0 0"/>
      <material name="Gazebo/Grey"/>
    </visual>
    <collision>
      <geometry>
        <cylinder length="0.02" radius="0.005"/>
      </geometry>
      <origin rpy="0 0 0" xyz="-0.0 0.0 0"/>
    </collision>
    <inertial>
      <mass value="0.001"/>
      <inertia ixx="1.9791666666666667e-07" ixy="0" ixz="0" iyy="1.9791666666666667e-07" iyz="0" izz="6.250000000000001e-08"/>
      <origin rpy="0 0 0" xyz="-0.0 0.0 0"/>
    </inertial>
  </link>
  <joint name="joint_tether_10" type="continuous">
    <origin rpy="0.0 0.0 0.0" xyz="0.0 0.0 0.02"/>
    <axis xyz="0 1 1"/>
    <!-- TODO(ff): not currently set because it's not yet supported -->
    <!-- <limit effort="2000" velocity="${max_rot_velocity}" /> -->
    <parent link="tether/link_09"/>
    <child link="tether/link_10"/>
  </joint>
  <link name="tether/link_11">
    <visual>
      <geometry>
        <cylinder length="0.02" radius="0.005"/>
      </geometry>
      <origin rpy="0 0 0" xyz="-0.0 0.0 0"/>
      <material name="Gazebo/Grey"/>
    </visual>
    <collision>
      <geometry>
        <cylinder length="0.02" radius="0.005"/>
      </geometry>
      <origin rpy="0 0 0" xyz="-0.0 0.0 0"/>
    </collision>
    <inertial>
      <mass value="0.001"/>
      <inertia ixx="1.9791666666666667e-07" ixy="0" ixz="0" iyy="1.9791666666666667e-07" iyz="0" izz="6.250000000000001e-08"/>
      <origin rpy="0 0 0" xyz="-0.0 0.0 0"/>
    </inertial>
  </link>
  <joint name="joint_tether_11" type="continuous">
    <origin rpy="0.0 0.0 0.0" xyz="0.0 0.0 0.02"/>
    <axis xyz="0 1 1"/>
    <!-- TODO(ff): not currently set because it's not yet supported -->
    <!-- <limit effort="2000" velocity="${max_rot_velocity}" /> -->
    <parent link="tether/link_10"/>
    <child link="tether/link_11"/>
  </joint>
  <link name="tether/link_12">
    <visual>
      <geometry>
        <cylinder length="0.02" radius="0.005"/>
      </geometry>
      <origin rpy="0 0 0" xyz="-0.0 0.0 0"/>
      <material name="Gazebo/Grey"/>
    </visual>
    <collision>
      <geometry>
        <cylinder length="0.02" radius="0.005"/>
      </geometry>
      <origin rpy="0 0 0" xyz="-0.0 0.0 0"/>
    </collision>
    <inertial>
      <mass value="0.001"/>
      <inertia ixx="1.9791666666666667e-07" ixy="0" ixz="0" iyy="1.9791666666666667e-07" iyz="0" izz="6.250000000000001e-08"/>
      <origin rpy="0 0 0" xyz="-0.0 0.0 0"/>
    </inertial>
  </link>
  <joint name="joint_tether_12" type="continuous">
    <origin rpy="0.0 0.0 0.0" xyz="0.0 0.0 0.02"/>
    <axis xyz="0 1 1"/>
    <!-- TODO(ff): not currently set because it's not yet supported -->
    <!-- <limit effort="2000" velocity="${max_rot_velocity}" /> -->
    <parent link="tether/link_11"/>
    <child link="tether/link_12"/>
  </joint>
  <link name="tether/link_13">
    <visual>
      <geometry>
        <cylinder length="0.02" radius="0.005"/>
      </geometry>
      <origin rpy="0 0 0" xyz="-0.0 0.0 0"/>
      <material name="Gazebo/Grey"/>
    </visual>
    <collision>
      <geometry>
        <cylinder length="0.02" radius="0.005"/>
      </geometry>
      <origin rpy="0 0 0" xyz="-0.0 0.0 0"/>
    </collision>
    <inertial>
      <mass value="0.001"/>
      <inertia ixx="1.9791666666666667e-07" ixy="0" ixz="0" iyy="1.9791666666666667e-07" iyz="0" izz="6.250000000000001e-08"/>
      <origin rpy="0 0 0" xyz="-0.0 0.0 0"/>
    </inertial>
  </link>
  <joint name="joint_tether_13" type="continuous">
    <origin rpy="0.0 0.0 0.0" xyz="0.0 0.0 0.02"/>
    <axis xyz="0 1 1"/>
    <!-- TODO(ff): not currently set because it's not yet supported -->
    <!-- <limit effort="2000" velocity="${max_rot_velocity}" /> -->
    <parent link="tether/link_12"/>
    <child link="tether/link_13"/>
  </joint>
  <link name="tether/link_14">
    <visual>
      <geometry>
        <cylinder length="0.02" radius="0.005"/>
      </geometry>
      <origin rpy="0 0 0" xyz="-0.0 0.0 0"/>
      <material name="Gazebo/Grey"/>
    </visual>
    <collision>
      <geometry>
        <cylinder length="0.02" radius="0.005"/>
      </geometry>
      <origin rpy="0 0 0" xyz="-0.0 0.0 0"/>
    </collision>
    <inertial>
      <mass value="0.001"/>
      <inertia ixx="1.9791666666666667e-07" ixy="0" ixz="0" iyy="1.9791666666666667e-07" iyz="0" izz="6.250000000000001e-08"/>
      <origin rpy="0 0 0" xyz="-0.0 0.0 0"/>
    </inertial>
  </link>
  <joint name="joint_tether_14" type="continuous">
    <origin rpy="0.0 0.0 0.0" xyz="0.0 0.0 0.02"/>
    <axis xyz="0 1 1"/>
    <!-- TODO(ff): not currently set because it's not yet supported -->
    <!-- <limit effort="2000" velocity="${max_rot_velocity}" /> -->
    <parent link="tether/link_13"/>
    <child link="tether/link_14"/>
  </joint>
  <link name="tether/link_15">
    <visual>
      <geometry>
        <cylinder length="0.02" radius="0.005"/>
      </geometry>
      <origin rpy="0 0 0" xyz="-0.0 0.0 0"/>
      <material name="Gazebo/Grey"/>
    </visual>
    <collision>
      <geometry>
        <cylinder length="0.02" radius="0.005"/>
      </geometry>
      <origin rpy="0 0 0" xyz="-0.0 0.0 0"/>
    </collision>
    <inertial>
      <mass value="0.001"/>
      <inertia ixx="1.9791666666666667e-07" ixy="0" ixz="0" iyy="1.9791666666666667e-07" iyz="0" izz="6.250000000000001e-08"/>
      <origin rpy="0 0 0" xyz="-0.0 0.0 0"/>
    </inertial>
  </link>
  <joint name="joint_tether_15" type="continuous">
    <origin rpy="0.0 0.0 0.0" xyz="0.0 0.0 0.02"/>
    <axis xyz="0 1 1"/>
    <!-- TODO(ff): not currently set because it's not yet supported -->
    <!-- <limit effort="2000" velocity="${max_rot_velocity}" /> -->
    <parent link="tether/link_14"/>
    <child link="tether/link_15"/>
  </joint>

  <link name="tether/link_16">
    <visual>
      <geometry>
        <cylinder length="0.02" radius="0.005"/>
      </geometry>
      <origin rpy="0 0 0" xyz="-0.0 0.0 0"/>
      <material name="Gazebo/Grey"/>
    </visual>
    <collision>
      <geometry>
        <cylinder length="0.02" radius="0.005"/>
      </geometry>
      <origin rpy="0 0 0" xyz="-0.0 0.0 0"/>
    </collision>
    <inertial>
      <mass value="0.001"/>
      <inertia ixx="1.9791666666666667e-07" ixy="0" ixz="0" iyy="1.9791666666666667e-07" iyz="0" izz="6.250000000000001e-08"/>
      <origin rpy="0 0 0" xyz="-0.0 0.0 0"/>
    </inertial>
  </link>
  <joint name="joint_tether_16" type="continuous">
    <origin rpy="0.0 0.0 0.0" xyz="0.0 0.0 0.02"/>
    <axis xyz="0 1 1"/>
    <!-- TODO(ff): not currently set because it's not yet supported -->
    <!-- <limit effort="2000" velocity="${max_rot_velocity}" /> -->
    <parent link="tether/link_15"/>
    <child link="tether/link_16"/>
  </joint>
  <link name="tether/link_17">
    <visual>
      <geometry>
        <cylinder length="0.02" radius="0.005"/>
      </geometry>
      <origin rpy="0 0 0" xyz="-0.0 0.0 0"/>
      <material name="Gazebo/Grey"/>
    </visual>
    <collision>
      <geometry>
        <cylinder length="0.02" radius="0.005"/>
      </geometry>
      <origin rpy="0 0 0" xyz="-0.0 0.0 0"/>
    </collision>
    <inertial>
      <mass value="0.001"/>
      <inertia ixx="1.9791666666666667e-07" ixy="0" ixz="0" iyy="1.9791666666666667e-07" iyz="0" izz="6.250000000000001e-08"/>
      <origin rpy="0 0 0" xyz="-0.0 0.0 0"/>
    </inertial>
  </link>
  <joint name="joint_tether_17" type="continuous">
    <origin rpy="0.0 0.0 0.0" xyz="0.0 0.0 0.02"/>
    <axis xyz="0 1 1"/>
    <!-- TODO(ff): not currently set because it's not yet supported -->
    <!-- <limit effort="2000" velocity="${max_rot_velocity}" /> -->
    <parent link="tether/link_16"/>
    <child link="tether/link_17"/>
  </joint>
  <link name="tether/link_18">
    <visual>
      <geometry>
        <cylinder length="0.02" radius="0.005"/>
      </geometry>
      <origin rpy="0 0 0" xyz="-0.0 0.0 0"/>
      <material name="Gazebo/Grey"/>
    </visual>
    <collision>
      <geometry>
        <cylinder length="0.02" radius="0.005"/>
      </geometry>
      <origin rpy="0 0 0" xyz="-0.0 0.0 0"/>
    </collision>
    <inertial>
      <mass value="0.001"/>
      <inertia ixx="1.9791666666666667e-07" ixy="0" ixz="0" iyy="1.9791666666666667e-07" iyz="0" izz="6.250000000000001e-08"/>
      <origin rpy="0 0 0" xyz="-0.0 0.0 0"/>
    </inertial>
  </link>
  <joint name="joint_tether_18" type="continuous">
    <origin rpy="0.0 0.0 0.0" xyz="0.0 0.0 0.02"/>
    <axis xyz="0 1 1"/>
    <!-- TODO(ff): not currently set because it's not yet supported -->
    <!-- <limit effort="2000" velocity="${max_rot_velocity}" /> -->
    <parent link="tether/link_17"/>
    <child link="tether/link_18"/>
  </joint>
  <link name="tether/link_19">
    <visual>
      <geometry>
        <cylinder length="0.02" radius="0.005"/>
      </geometry>
      <origin rpy="0 0 0" xyz="-0.0 0.0 0"/>
      <material name="Gazebo/Grey"/>
    </visual>
    <collision>
      <geometry>
        <cylinder length="0.02" radius="0.005"/>
      </geometry>
      <origin rpy="0 0 0" xyz="-0.0 0.0 0"/>
    </collision>
    <inertial>
      <mass value="0.001"/>
      <inertia ixx="1.9791666666666667e-07" ixy="0" ixz="0" iyy="1.9791666666666667e-07" iyz="0" izz="6.250000000000001e-08"/>
      <origin rpy="0 0 0" xyz="-0.0 0.0 0"/>
    </inertial>
  </link>
  <joint name="joint_tether_19" type="continuous">
    <origin rpy="0.0 0.0 0.0" xyz="0.0 0.0 0.02"/>
    <axis xyz="0 1 1"/>
    <!-- TODO(ff): not currently set because it's not yet supported -->
    <!-- <limit effort="2000" velocity="${max_rot_velocity}" /> -->
    <parent link="tether/link_18"/>
    <child link="tether/link_19"/>
  </joint>
  
  <link name="tether/link_20">
    <visual>
      <geometry>
        <cylinder length="0.02" radius="0.005"/>
      </geometry>
      <origin rpy="0 0 0" xyz="-0.0 0.0 0"/>
      <material name="Gazebo/Grey"/>
    </visual>
    <collision>
      <geometry>
        <cylinder length="0.02" radius="0.005"/>
      </geometry>
      <origin rpy="0 0 0" xyz="-0.0 0.0 0"/>
    </collision>
    <inertial>
      <mass value="0.001"/>
      <inertia ixx="1.9791666666666667e-07" ixy="0" ixz="0" iyy="1.9791666666666667e-07" iyz="0" izz="6.250000000000001e-08"/>
      <origin rpy="0 0 0" xyz="-0.0 0.0 0"/>
    </inertial>
  </link>
  <joint name="joint_tether_20" type="continuous">
    <origin rpy="0.0 0.0 0.0" xyz="0.0 0.0 0.02"/>
    <axis xyz="0 1 1"/>
    <!-- TODO(ff): not currently set because it's not yet supported -->
    <!-- <limit effort="2000" velocity="${max_rot_velocity}" /> -->
    <parent link="tether/link_19"/>
    <child link="tether/link_20"/>
  </joint>

  <gazebo>
    <plugin filename="libgazebo_ros_modelate_tether.so" name="gazebo_ros_modelate_tether">
      <namespace>marsupial_tether</namespace>
      <numLinkTether>20</numLinkTether>
      <nameLinkFrame>link_tether</nameLinkFrame>
      <initLengthTether>0.5</initLengthTether>  <!-- Initial Tether length given by distance between UGV and UAV -->
    </plugin>
  </gazebo>
 
 <!-- .........................................................UAV STUFF.................................................................... -->
 
  <!-- <link name="firefly/base_link"/> -->

  <!-- <joint name="joint_tether_21" type="fixed">
    <origin rpy="0 0 0" xyz="0 0 0.1"/>
    <parent link="link_tether_20"/>
    <child link="firefly/base_link"/>
  </joint>   -->
  

  <link name="firefly/base_link">
    <inertial>
      <mass value="1.5"/>
      <!-- [kg] -->
      <origin xyz="0 0 0"/>
      <inertia ixx="0.0347563" ixy="0.0" ixz="0.0" iyy="0.0458929" iyz="0.0" izz="0.0977"/>
    </inertial>
    <visual>
      <origin rpy="0 0 0" xyz="0 0 0"/>
      <geometry>
        <mesh filename="package://marsupial_description/meshes/uav/firefly.dae" scale="1 1 1"/>
      </geometry>
    </visual>
    <collision>
      <origin rpy="0 0 0" xyz="0 0 0"/>
      <geometry>
        <box size="0.1 0.1 0.16"/>
        <!-- [m] [m] [m] -->
      </geometry>
    </collision>
  </link>

  <joint name="tether_to_uav" type="fixed">
    <origin rpy="0 0 0" xyz="0 0 0"/>
    <parent link="link_tether_20"/>
    <child link="firefly/base_link"/>
  </joint>

  <!-- <joint name="firefly/base_joint" type="fixed">
    <origin rpy="0 0 0" xyz="0 0 0"/>
    <parent link="firefly/base_link"/>
    <child link="firefly/base_link_inertia"/>
  </joint> -->

  <!-- attach multirotor_base_plugin to the base_link -->
  <gazebo>
    <plugin filename="librotors_gazebo_multirotor_base_plugin.so" name="multirotor_base_plugin">
      <robotNamespace>firefly</robotNamespace>
      <linkName>firefly/base_link</linkName>
      <rotorVelocitySlowdownSim>10</rotorVelocitySlowdownSim>
    </plugin>
  </gazebo>

  <joint name="firefly/rotor_0_joint" type="continuous">
    <origin rpy="0 0 0" xyz="0.18619546181355998 0.1075 0.037"/>
    <axis xyz="0 0 1"/>
    <parent link="firefly/base_link"/>
    <child link="firefly/rotor_0"/>
  </joint>

  <link name="firefly/rotor_0">
    <inertial>
      <mass value="0.005"/>
      <!-- [kg] -->
      <inertia ixx="9.7499961e-07" ixy="0.0" ixz="0.0" iyy="4.170414998500001e-05" iyz="0.0" izz="4.2604149625000006e-05"/>
    </inertial>
    <visual>
      <geometry>
        <mesh filename="package://marsupial_description/meshes/uav/propeller_ccw.dae" scale="0.1 0.1 0.1"/>
      </geometry>
    </visual>
    <collision>
      <geometry>
        <cylinder length="0.005" radius="0.1"/>
        <!-- [m] -->
      </geometry>
    </collision>
  </link>

  <gazebo>
    <plugin filename="librotors_gazebo_motor_model.so" name="firefly_front_left_motor_model">
      <robotNamespace>firefly</robotNamespace>
      <jointName>firefly/rotor_0_joint</jointName>
      <linkName>firefly/rotor_0</linkName>
      <turningDirection>ccw</turningDirection>
      <timeConstantUp>0.0125</timeConstantUp>
      <timeConstantDown>0.025</timeConstantDown>
      <maxRotVelocity>838</maxRotVelocity>
      <motorConstant>8.54858e-06</motorConstant>
      <momentConstant>0.016</momentConstant>
      <commandSubTopic>gazebo/command/motor_speed</commandSubTopic>
      <motorNumber>0</motorNumber>
      <rotorDragCoefficient>8.06428e-05</rotorDragCoefficient>
      <rollingMomentCoefficient>1e-06</rollingMomentCoefficient>
      <motorSpeedPubTopic>motor_speed/0</motorSpeedPubTopic>
      <rotorVelocitySlowdownSim>10</rotorVelocitySlowdownSim>
    </plugin>
  </gazebo>

  <gazebo reference="firefly/rotor_0">
    <material>Gazebo/Red</material>
  </gazebo>
  <joint name="firefly/rotor_1_joint" type="continuous">
    <origin rpy="0 0 0" xyz="0 0.215 0.037"/>
    <axis xyz="0 0 1"/>
    <!-- TODO(ff): not currently set because it's not yet supported -->
    <!-- <limit effort="2000" velocity="${max_rot_velocity}" /> -->
    <parent link="firefly/base_link"/>
    <child link="firefly/rotor_1"/>
  </joint>
  <link name="firefly/rotor_1">
    <inertial>
      <mass value="0.005"/>
      <!-- [kg] -->
      <inertia ixx="9.7499961e-07" ixy="0.0" ixz="0.0" iyy="4.170414998500001e-05" iyz="0.0" izz="4.2604149625000006e-05"/>
    </inertial>
    <visual>
      <geometry>
        <mesh filename="package://marsupial_description/meshes/uav/propeller_cw.dae" scale="0.1 0.1 0.1"/>
        <!-- The propeller meshes have a radius of 1m -->
        <!-- <box size="${2*radius_rotor} 0.01 0.005"/> -->
      </geometry>
    </visual>
    <collision>
      <geometry>
        <cylinder length="0.005" radius="0.1"/>
        <!-- [m] -->
      </geometry>
    </collision>
  </link>
  <gazebo>
  
    <plugin filename="librotors_gazebo_motor_model.so" name="firefly_left_motor_model">
      <robotNamespace>firefly</robotNamespace>
      <jointName>firefly/rotor_1_joint</jointName>
      <linkName>firefly/rotor_1</linkName>
      <turningDirection>cw</turningDirection>
      <timeConstantUp>0.0125</timeConstantUp>
      <timeConstantDown>0.025</timeConstantDown>
      <maxRotVelocity>838</maxRotVelocity>
      <motorConstant>8.54858e-06</motorConstant>
      <momentConstant>0.016</momentConstant>
      <commandSubTopic>gazebo/command/motor_speed</commandSubTopic>
      <motorNumber>1</motorNumber>
      <rotorDragCoefficient>8.06428e-05</rotorDragCoefficient>
      <rollingMomentCoefficient>1e-06</rollingMomentCoefficient>
      <motorSpeedPubTopic>motor_speed/1</motorSpeedPubTopic>
      <rotorVelocitySlowdownSim>10</rotorVelocitySlowdownSim>
    </plugin>
  </gazebo>

  <gazebo reference="firefly/rotor_1">
    <material>Gazebo/Blue</material>
  </gazebo>

  <joint name="firefly/rotor_2_joint" type="continuous">
    <origin rpy="0 0 0" xyz="-0.18619546181355998 0.1075 0.037"/>
    <axis xyz="0 0 1"/>
    <parent link="firefly/base_link"/>
    <child link="firefly/rotor_2"/>
  </joint>
  <link name="firefly/rotor_2">
    <inertial>
      <mass value="0.005"/>
      <!-- [kg] -->
      <inertia ixx="9.7499961e-07" ixy="0.0" ixz="0.0" iyy="4.170414998500001e-05" iyz="0.0" izz="4.2604149625000006e-05"/>
    </inertial>
    <visual>
      <geometry>
        <mesh filename="package://marsupial_description/meshes/uav/propeller_ccw.dae" scale="0.1 0.1 0.1"/>
      </geometry>
    </visual>
    <collision>
      <geometry>
        <cylinder length="0.005" radius="0.1"/>
        <!-- [m] -->
      </geometry>
    </collision>
  </link>

  <gazebo>
    <plugin filename="librotors_gazebo_motor_model.so" name="firefly_back_left_motor_model">
      <robotNamespace>firefly</robotNamespace>
      <jointName>firefly/rotor_2_joint</jointName>
      <linkName>firefly/rotor_2</linkName>
      <turningDirection>ccw</turningDirection>
      <timeConstantUp>0.0125</timeConstantUp>
      <timeConstantDown>0.025</timeConstantDown>
      <maxRotVelocity>838</maxRotVelocity>
      <motorConstant>8.54858e-06</motorConstant>
      <momentConstant>0.016</momentConstant>
      <commandSubTopic>gazebo/command/motor_speed</commandSubTopic>
      <motorNumber>2</motorNumber>
      <rotorDragCoefficient>8.06428e-05</rotorDragCoefficient>
      <rollingMomentCoefficient>1e-06</rollingMomentCoefficient>
      <motorSpeedPubTopic>motor_speed/2</motorSpeedPubTopic>
      <rotorVelocitySlowdownSim>10</rotorVelocitySlowdownSim>
    </plugin>
  </gazebo>

  <gazebo reference="firefly/rotor_2">
    <material>Gazebo/Blue</material>
  </gazebo>

  <joint name="firefly/rotor_3_joint" type="continuous">
    <origin rpy="0 0 0" xyz="-0.18619546181355998 -0.1075 0.037"/>
    <axis xyz="0 0 1"/>
    <parent link="firefly/base_link"/>
    <child link="firefly/rotor_3"/>
  </joint>

  <link name="firefly/rotor_3">
    <inertial>
      <mass value="0.005"/>
      <!-- [kg] -->
      <inertia ixx="9.7499961e-07" ixy="0.0" ixz="0.0" iyy="4.170414998500001e-05" iyz="0.0" izz="4.2604149625000006e-05"/>
    </inertial>
    <visual>
      <geometry>
        <mesh filename="package://marsupial_description/meshes/uav/propeller_cw.dae" scale="0.1 0.1 0.1"/>
      </geometry>
    </visual>
    <collision>
      <geometry>
        <cylinder length="0.005" radius="0.1"/>
        <!-- [m] -->
      </geometry>
    </collision>
  </link>

  <gazebo>
    <plugin filename="librotors_gazebo_motor_model.so" name="firefly_back_right_motor_model">
      <robotNamespace>firefly</robotNamespace>
      <jointName>firefly/rotor_3_joint</jointName>
      <linkName>firefly/rotor_3</linkName>
      <turningDirection>cw</turningDirection>
      <timeConstantUp>0.0125</timeConstantUp>
      <timeConstantDown>0.025</timeConstantDown>
      <maxRotVelocity>838</maxRotVelocity>
      <motorConstant>8.54858e-06</motorConstant>
      <momentConstant>0.016</momentConstant>
      <commandSubTopic>gazebo/command/motor_speed</commandSubTopic>
      <motorNumber>3</motorNumber>
      <rotorDragCoefficient>8.06428e-05</rotorDragCoefficient>
      <rollingMomentCoefficient>1e-06</rollingMomentCoefficient>
      <motorSpeedPubTopic>motor_speed/3</motorSpeedPubTopic>
      <rotorVelocitySlowdownSim>10</rotorVelocitySlowdownSim>
    </plugin>
  </gazebo>

  <gazebo reference="firefly/rotor_3">
    <material>Gazebo/Blue</material>
  </gazebo>

  <joint name="firefly/rotor_4_joint" type="continuous">
    <origin rpy="0 0 0" xyz="0 -0.215 0.037"/>
    <axis xyz="0 0 1"/>
    <parent link="firefly/base_link"/>
    <child link="firefly/rotor_4"/>
  </joint>

  <link name="firefly/rotor_4">
    <inertial>
      <mass value="0.005"/>
      <!-- [kg] -->
      <inertia ixx="9.7499961e-07" ixy="0.0" ixz="0.0" iyy="4.170414998500001e-05" iyz="0.0" izz="4.2604149625000006e-05"/>
    </inertial>
    <visual>
      <geometry>
        <mesh filename="package://marsupial_description/meshes/uav/propeller_ccw.dae" scale="0.1 0.1 0.1"/>
      </geometry>
    </visual>
    <collision>
      <geometry>
        <cylinder length="0.005" radius="0.1"/>
        <!-- [m] -->
      </geometry>
    </collision>
  </link>

  <gazebo>
    <plugin filename="librotors_gazebo_motor_model.so" name="firefly_right_motor_model">
      <robotNamespace>firefly</robotNamespace>
      <jointName>firefly/rotor_4_joint</jointName>
      <linkName>firefly/rotor_4</linkName>
      <turningDirection>ccw</turningDirection>
      <timeConstantUp>0.0125</timeConstantUp>
      <timeConstantDown>0.025</timeConstantDown>
      <maxRotVelocity>838</maxRotVelocity>
      <motorConstant>8.54858e-06</motorConstant>
      <momentConstant>0.016</momentConstant>
      <commandSubTopic>gazebo/command/motor_speed</commandSubTopic>
      <motorNumber>4</motorNumber>
      <rotorDragCoefficient>8.06428e-05</rotorDragCoefficient>
      <rollingMomentCoefficient>1e-06</rollingMomentCoefficient>
      <motorSpeedPubTopic>motor_speed/4</motorSpeedPubTopic>
      <rotorVelocitySlowdownSim>10</rotorVelocitySlowdownSim>
    </plugin>
  </gazebo>

  <gazebo reference="firefly/rotor_4">
    <material>Gazebo/Blue</material>
  </gazebo>

  <joint name="firefly/rotor_5_joint" type="continuous">
    <origin rpy="0 0 0" xyz="0.18619546181355998 -0.1075 0.037"/>
    <axis xyz="0 0 1"/>
    <parent link="firefly/base_link"/>
    <child link="firefly/rotor_5"/>
  </joint>

  <link name="firefly/rotor_5">
    <inertial>
      <mass value="0.005"/>
      <!-- [kg] -->
      <inertia ixx="9.7499961e-07" ixy="0.0" ixz="0.0" iyy="4.170414998500001e-05" iyz="0.0" izz="4.2604149625000006e-05"/>
    </inertial>
    <visual>
      <geometry>
        <mesh filename="package://marsupial_description/meshes/uav/propeller_cw.dae" scale="0.1 0.1 0.1"/>
      </geometry>
    </visual>
    <collision>
      <geometry>
        <cylinder length="0.005" radius="0.1"/>
        <!-- [m] -->
      </geometry>
    </collision>
  </link>

  <gazebo>
    <plugin filename="librotors_gazebo_motor_model.so" name="firefly_front_right_motor_model">
      <robotNamespace>firefly</robotNamespace>
      <jointName>firefly/rotor_5_joint</jointName>
      <linkName>firefly/rotor_5</linkName>
      <turningDirection>cw</turningDirection>
      <timeConstantUp>0.0125</timeConstantUp>
      <timeConstantDown>0.025</timeConstantDown>
      <maxRotVelocity>838</maxRotVelocity>
      <motorConstant>8.54858e-06</motorConstant>
      <momentConstant>0.016</momentConstant>
      <commandSubTopic>gazebo/command/motor_speed</commandSubTopic>
      <motorNumber>5</motorNumber>
      <rotorDragCoefficient>8.06428e-05</rotorDragCoefficient>
      <rollingMomentCoefficient>1e-06</rollingMomentCoefficient>
      <motorSpeedPubTopic>motor_speed/5</motorSpeedPubTopic>
      <rotorVelocitySlowdownSim>10</rotorVelocitySlowdownSim>
    </plugin>
  </gazebo>

  <gazebo reference="firefly/rotor_5">
    <material>Gazebo/Red</material>
  </gazebo>

  <gazebo>
    <plugin filename="librotors_gazebo_controller_interface.so" name="controller_interface">
      <robotNamespace>firefly</robotNamespace>
      <commandAttitudeThrustSubTopic>command/attitude</commandAttitudeThrustSubTopic>
      <commandRateThrustSubTopic>command/rate</commandRateThrustSubTopic>
      <commandMotorSpeedSubTopic>command/motor_speed</commandMotorSpeedSubTopic>
      <imuSubTopic>imu</imuSubTopic>
      <motorSpeedCommandPubTopic>gazebo/command/motor_speed</motorSpeedCommandPubTopic>
    </plugin>
  </gazebo>

  <!-- Instantiate a ROS message interface -->
  <!-- <xacro:ros_interface_plugin_macro namespace="firefly" />-->
  <!-- IMU link -->
  <link name="firefly/imu_link">
    <inertial>
      <inertia ixx="0.00001" ixy="0.0" ixz="0.0" iyy="0.00001" iyz="0.0" izz="0.00001"/>
      <mass value="0.015"/>
      <!-- [kg] -->
      <origin rpy="0 0 0" xyz="0 0 0"/>
    </inertial>
  </link>

  <!-- IMU joint -->
  <joint name="firefly/imu_joint" type="revolute">
    <origin rpy="0 0 0" xyz="0 0 0"/>
    <parent link="firefly/base_link"/>
    <child link="firefly/imu_link"/>
    <limit effort="0" lower="0" upper="0" velocity="0"/>
  </joint>

  <gazebo>
    <plugin filename="librotors_gazebo_imu_plugin.so" name="rotors_gazebo_imu_plugin">
      <!-- A good description of the IMU parameters can be found in the kalibr documentation:
           https://github.com/ethz-asl/kalibr/wiki/IMU-Noise-Model-and-Intrinsics -->
      <robotNamespace>firefly</robotNamespace>
      <!-- (string, required): ros namespace in which the messages are published -->
      <linkName>firefly/imu_link</linkName>
      <!-- (string, required): name of the body which holds the IMU sensor -->
      <imuTopic>imu</imuTopic>
      <!-- (string): name of the sensor output topic and prefix of service names (defaults to imu) -->
      <gyroscopeNoiseDensity>0.0003394</gyroscopeNoiseDensity>
      <!-- Gyroscope noise density (two-sided spectrum) [rad/s/sqrt(Hz)] -->
      <gyroscopeRandomWalk>3.8785e-05</gyroscopeRandomWalk>
      <!-- Gyroscope bias random walk [rad/s/s/sqrt(Hz)] -->
      <gyroscopeBiasCorrelationTime>1000.0</gyroscopeBiasCorrelationTime>
      <!-- Gyroscope bias correlation time constant [s] -->
      <gyroscopeTurnOnBiasSigma>0.0087</gyroscopeTurnOnBiasSigma>
      <!-- Gyroscope turn on bias standard deviation [rad/s] -->
      <accelerometerNoiseDensity>0.004</accelerometerNoiseDensity>
      <!-- Accelerometer noise density (two-sided spectrum) [m/s^2/sqrt(Hz)] -->
      <accelerometerRandomWalk>0.006</accelerometerRandomWalk>
      <!-- Accelerometer bias random walk. [m/s^2/s/sqrt(Hz)] -->
      <accelerometerBiasCorrelationTime>300.0</accelerometerBiasCorrelationTime>
      <!-- Accelerometer bias correlation time constant [s] -->
      <accelerometerTurnOnBiasSigma>0.196</accelerometerTurnOnBiasSigma>
      <!-- Accelerometer turn on bias standard deviation [m/s^2] -->
    </plugin>
  </gazebo>

  <link name="firefly/os1_sensor">
      <inertial>
         <inertia ixx="0.000090623" ixy="0.0" ixz="0.0" iyy="0.000090623" iyz="0.0" izz="0.000091036" /> -->
         <mass value="0.01" />
         <inertia ixx="1e-6" ixy="0.0" ixz="0.0" iyy="1e-6" iyz="0.0" izz="1e-6" /> 
      </inertial>
    </link>
    <link name="firefly/velodyne_base">
      <inertial>
         <inertia ixx="0.001087473" ixy="0.0" ixz="0.0" iyy="0.001087473" iyz="0.0" izz="0.001092437" /> -->
         <mass value="0.01" />
         <inertia ixx="1e-6" ixy="0.0" ixz="0.0" iyy="1e-6" iyz="0.0" izz="1e-6" /> 
      </inertial>
    </link>
    <joint type="fixed" name="joint">
      <origin xyz="0 0 -0.036785" rpy="0 0 0" />
      <parent link="firefly/velodyne_base" />
      <child link="firefly/os1_sensor" />
      <axis>
        <xyz>0 0 1</xyz>
        <limit>
          <lower>-10000000000000000</lower>
          <upper>10000000000000000</upper>
        </limit>
      </axis>
    </joint>
    <joint type="fixed" name="fixed_velodyne">
      <origin xyz="0 0 0" rpy="0 0 0" />
      <parent link="firefly/base_link" />
      <child link="firefly/velodyne_base" />
    </joint>
    <gazebo reference="firefly/os1_sensor">
     <sensor type="ray" name="laser_scan">
      <pose>0 0 -0.004645 0 0 0</pose>
      <visualize>false</visualize>
      <update_rate>10</update_rate>
      <ray>
        <scan>
            <horizontal>
              <samples>512</samples>
              <resolution>1</resolution>
              <min_angle>-3.14159</min_angle>
              <max_angle>3.14159</max_angle>
            </horizontal>
            <vertical>
              <samples>16</samples>
              <resolution>1</resolution>
              <min_angle>-0.2897247</min_angle>
              <max_angle>0.2897247</max_angle>
            </vertical>
        </scan>
        <range>
            <min>0.8</min>
            <max>120</max>
            <resolution>0.012</resolution>
        </range>
        <noise>
            <type>gaussian</type>
            <mean>0.0</mean>
            <stddev>0.0</stddev>
        </noise>
      </ray>
      <plugin name="firefly_gazebo_ros_laser_controller" filename="libgazebo_ros_velodyne_laser.so">
          <!--<topicName>firefly/os1_cloud_node/points</topicName> -->
          <topicName>firefly/os1_cloud_node/points</topicName>
          <frameName>firefly/os1_sensor</frameName>
          <min_range>0.8</min_range>
          <max_range>120.0</max_range>
          <gaussianNoise>0.03</gaussianNoise>  
      </plugin>
     </sensor>
    </gazebo>

  <!-- odometry link -->
  <link name="firefly/odometry_sensor1_link">
    <inertial>
      <inertia ixx="0.00001" ixy="0.0" ixz="0.0" iyy="0.00001" iyz="0.0" izz="0.00001"/>
      <mass value="1e-05"/>
      <!-- [kg] -->
    </inertial>
  </link>

  <!-- odometry joint -->
  <joint name="firefly/odometry_sensor1_joint" type="revolute">
    <parent link="firefly/base_link"/>
    <origin rpy="0.0 0.0 0.0" xyz="0.0 0.0 0.0"/>
    <child link="firefly/odometry_sensor1_link"/>
    <limit effort="0" lower="0" upper="0" velocity="0"/>
  </joint>
  
  <gazebo>
    <plugin filename="librotors_gazebo_odometry_plugin.so" name="odometry_sensor1">
      <linkName>firefly/odometry_sensor1_link</linkName>
      <robotNamespace>firefly</robotNamespace>
      <poseTopic>pose</poseTopic>
      <poseWithCovarianceTopic>pose_with_covariance</poseWithCovarianceTopic>
      <positionTopic>ground_truth/position</positionTopic>
      <transformTopic>ground_truth/transform</transformTopic>
      <odometryTopic>ground_truth/odometry</odometryTopic>
      <parentFrameId>world</parentFrameId>
      <!-- Use the scoped link name here. e.g. Model::link. -->
      <childFrameId>firefly/odometry_sensor1</childFrameId>
      <measurementDivisor>1</measurementDivisor>
      <!-- only every (seq % measurementDivisor) == 0 measurement is published [int] -->
      <measurementDelay>0</measurementDelay>
      <!-- time that measurement gets held back before it's published in [simulation cycles (int)] -->
      <unknownDelay>0.0</unknownDelay>
      <!-- additional delay, that just gets added to the timestamp [s] -->
      <noiseNormalPosition>0 0 0</noiseNormalPosition>
      <!-- standard deviation of additive white gaussian noise [m] -->
      <noiseNormalQuaternion>0 0 0</noiseNormalQuaternion>
      <!-- standard deviation white gaussian noise [rad]: q_m = q*quaternionFromSmallAngleApproximation(noiseNormalQ) -->
      <noiseNormalLinearVelocity>0 0 0</noiseNormalLinearVelocity>
      <!-- standard deviation of additive white gaussian noise [m/s] -->
      <noiseNormalAngularVelocity>0 0 0</noiseNormalAngularVelocity>
      <!-- standard deviation of additive white gaussian noise [rad/s] -->
      <noiseUniformPosition>0 0 0</noiseUniformPosition>
      <!-- symmetric bounds of uniform noise [m] -->
      <noiseUniformQuaternion>0 0 0</noiseUniformQuaternion>
      <!-- symmetric bounds of uniform noise [rad], computation see above -->
      <noiseUniformLinearVelocity>0 0 0</noiseUniformLinearVelocity>
      <!-- symmetric bounds of uniform noise [m/s] -->
      <noiseUniformAngularVelocity>0 0 0</noiseUniformAngularVelocity>
    </plugin>
  </gazebo>


</robot>

