<?xml version="1.0" ?>
<!-- =================================================================================== -->
<!-- |    This document was autogenerated by xacro from tether.xacro                   | -->
<!-- |    EDITING THIS FILE BY HAND IS NOT RECOMMENDED                                 | -->
<!-- =================================================================================== -->
<robot name="tether_model">

  <link name="tether/link_1">
    <visual>
      <geometry>
        <cylinder length="0.02" radius="0.005"/>
      </geometry>
      <origin rpy="0 0 0" xyz="-0.0 0.0 0"/>
      <material name="Gazebo/Grey"/>
    </visual>
    <collision>
      <geometry>
        <cylinder length="0.02" radius="0.005"/>
      </geometry>
      <origin rpy="0 0 0" xyz="-0.0 0.0 0"/>
    </collision>
    <inertial>
      <mass value="0.001"/>
      <inertia ixx="1.9791666666666667e-07" ixy="0" ixz="0" iyy="1.9791666666666667e-07" iyz="0" izz="6.250000000000001e-08"/>
      <origin rpy="0 0 0" xyz="-0.0 0.0 0"/>
    </inertial>
  </link>
  <link name="tether/link_02">
    <visual>
      <geometry>
        <cylinder length="0.02" radius="0.005"/>
      </geometry>
      <origin rpy="0 0 0" xyz="-0.0 0.0 0"/>
      <material name="Gazebo/Grey"/>
    </visual>
    <collision>
      <geometry>
        <cylinder length="0.02" radius="0.005"/>
      </geometry>
      <origin rpy="0 0 0" xyz="-0.0 0.0 0"/>
    </collision>
    <inertial>
      <mass value="0.001"/>
      <inertia ixx="1.9791666666666667e-07" ixy="0" ixz="0" iyy="1.9791666666666667e-07" iyz="0" izz="6.250000000000001e-08"/>
      <origin rpy="0 0 0" xyz="-0.0 0.0 0"/>
    </inertial>
  </link>

  <joint name="joint_tether_2" type="continuous">
    <origin rpy="0.0 0.0 0.0" xyz="0.0 0.0 0.02"/>
    <axis xyz="0 1 1"/>
    <!-- TODO(ff): not currently set because it's not yet supported -->
    <!-- <limit effort="2000" velocity="${max_rot_velocity}" /> -->
    <parent link="tether/link_1"/>
    <child link="tether/link_02"/>
  </joint>

  <link name="tether/link_03">
    <visual>
      <geometry>
        <cylinder length="0.02" radius="0.005"/>
      </geometry>
      <origin rpy="0 0 0" xyz="-0.0 0.0 0"/>
      <material name="Gazebo/Grey"/>
    </visual>
    <collision>
      <geometry>
        <cylinder length="0.02" radius="0.005"/>
      </geometry>
      <origin rpy="0 0 0" xyz="-0.0 0.0 0"/>
    </collision>
    <inertial>
      <mass value="0.001"/>
      <inertia ixx="1.9791666666666667e-07" ixy="0" ixz="0" iyy="1.9791666666666667e-07" iyz="0" izz="6.250000000000001e-08"/>
      <origin rpy="0 0 0" xyz="-0.0 0.0 0"/>
    </inertial>
  </link>

  <joint name="joint_tether_3" type="continuous">
    <origin rpy="0.0 0.0 0.0" xyz="0.0 0.0 0.02"/>
    <axis xyz="0 1 1"/>
    <!-- TODO(ff): not currently set because it's not yet supported -->
    <!-- <limit effort="2000" velocity="${max_rot_velocity}" /> -->
    <parent link="tether/link_02"/>
    <child link="tether/link_03"/>
  </joint>

  <link name="tether/link_04">
    <visual>
      <geometry>
        <cylinder length="0.02" radius="0.005"/>
      </geometry>
      <origin rpy="0 0 0" xyz="-0.0 0.0 0"/>
      <material name="Gazebo/Grey"/>
    </visual>
    <collision>
      <geometry>
        <cylinder length="0.02" radius="0.005"/>
      </geometry>
      <origin rpy="0 0 0" xyz="-0.0 0.0 0"/>
    </collision>
    <inertial>
      <mass value="0.001"/>
      <inertia ixx="1.9791666666666667e-07" ixy="0" ixz="0" iyy="1.9791666666666667e-07" iyz="0" izz="6.250000000000001e-08"/>
      <origin rpy="0 0 0" xyz="-0.0 0.0 0"/>
    </inertial>
  </link>
  <joint name="joint_tether_4" type="continuous">
    <origin rpy="0.0 0.0 0.0" xyz="0.0 0.0 0.02"/>
    <axis xyz="0 1 1"/>
    <!-- TODO(ff): not currently set because it's not yet supported -->
    <!-- <limit effort="2000" velocity="${max_rot_velocity}" /> -->
    <parent link="tether/link_03"/>
    <child link="tether/link_04"/>
  </joint>
  <link name="tether/link_05">
    <visual>
      <geometry>
        <cylinder length="0.02" radius="0.005"/>
      </geometry>
      <origin rpy="0 0 0" xyz="-0.0 0.0 0"/>
      <material name="Gazebo/Grey"/>
    </visual>
    <collision>
      <geometry>
        <cylinder length="0.02" radius="0.005"/>
      </geometry>
      <origin rpy="0 0 0" xyz="-0.0 0.0 0"/>
    </collision>
    <inertial>
      <mass value="0.001"/>
      <inertia ixx="1.9791666666666667e-07" ixy="0" ixz="0" iyy="1.9791666666666667e-07" iyz="0" izz="6.250000000000001e-08"/>
      <origin rpy="0 0 0" xyz="-0.0 0.0 0"/>
    </inertial>
  </link>
  <joint name="joint_tether_5" type="continuous">
    <origin rpy="0.0 0.0 0.0" xyz="0.0 0.0 0.02"/>
    <axis xyz="0 1 1"/>
    <!-- TODO(ff): not currently set because it's not yet supported -->
    <!-- <limit effort="2000" velocity="${max_rot_velocity}" /> -->
    <parent link="tether/link_04"/>
    <child link="tether/link_05"/>
  </joint>
  
  <link name="tether/link_06">
    <visual>
      <geometry>
        <cylinder length="0.02" radius="0.005"/>
      </geometry>
      <origin rpy="0 0 0" xyz="-0.0 0.0 0"/>
      <material name="Gazebo/Grey"/>
    </visual>
    <collision>
      <geometry>
        <cylinder length="0.02" radius="0.005"/>
      </geometry>
      <origin rpy="0 0 0" xyz="-0.0 0.0 0"/>
    </collision>
    <inertial>
      <mass value="0.001"/>
      <inertia ixx="1.9791666666666667e-07" ixy="0" ixz="0" iyy="1.9791666666666667e-07" iyz="0" izz="6.250000000000001e-08"/>
      <origin rpy="0 0 0" xyz="-0.0 0.0 0"/>
    </inertial>
  </link>
  <joint name="joint_tether_6" type="continuous">
    <origin rpy="0.0 0.0 0.0" xyz="0.0 0.0 0.02"/>
    <axis xyz="0 1 1"/>
    <!-- TODO(ff): not currently set because it's not yet supported -->
    <!-- <limit effort="2000" velocity="${max_rot_velocity}" /> -->
    <parent link="tether/link_05"/>
    <child link="tether/link_06"/>
  </joint>
  <link name="tether/link_07">
    <visual>
      <geometry>
        <cylinder length="0.02" radius="0.005"/>
      </geometry>
      <origin rpy="0 0 0" xyz="-0.0 0.0 0"/>
      <material name="Gazebo/Grey"/>
    </visual>
    <collision>
      <geometry>
        <cylinder length="0.02" radius="0.005"/>
      </geometry>
      <origin rpy="0 0 0" xyz="-0.0 0.0 0"/>
    </collision>
    <inertial>
      <mass value="0.001"/>
      <inertia ixx="1.9791666666666667e-07" ixy="0" ixz="0" iyy="1.9791666666666667e-07" iyz="0" izz="6.250000000000001e-08"/>
      <origin rpy="0 0 0" xyz="-0.0 0.0 0"/>
    </inertial>
  </link>
  <joint name="joint_tether_7" type="continuous">
    <origin rpy="0.0 0.0 0.0" xyz="0.0 0.0 0.02"/>
    <axis xyz="0 1 1"/>
    <!-- TODO(ff): not currently set because it's not yet supported -->
    <!-- <limit effort="2000" velocity="${max_rot_velocity}" /> -->
    <parent link="tether/link_06"/>
    <child link="tether/link_07"/>
  </joint>
  <link name="tether/link_08">
    <visual>
      <geometry>
        <cylinder length="0.02" radius="0.005"/>
      </geometry>
      <origin rpy="0 0 0" xyz="-0.0 0.0 0"/>
      <material name="Gazebo/Grey"/>
    </visual>
    <collision>
      <geometry>
        <cylinder length="0.02" radius="0.005"/>
      </geometry>
      <origin rpy="0 0 0" xyz="-0.0 0.0 0"/>
    </collision>
    <inertial>
      <mass value="0.001"/>
      <inertia ixx="1.9791666666666667e-07" ixy="0" ixz="0" iyy="1.9791666666666667e-07" iyz="0" izz="6.250000000000001e-08"/>
      <origin rpy="0 0 0" xyz="-0.0 0.0 0"/>
    </inertial>
  </link>
  <joint name="joint_tether_8" type="continuous">
    <origin rpy="0.0 0.0 0.0" xyz="0.0 0.0 0.02"/>
    <axis xyz="0 1 1"/>
    <!-- TODO(ff): not currently set because it's not yet supported -->
    <!-- <limit effort="2000" velocity="${max_rot_velocity}" /> -->
    <parent link="tether/link_07"/>
    <child link="tether/link_08"/>
  </joint>
  <link name="tether/link_09">
    <visual>
      <geometry>
        <cylinder length="0.02" radius="0.005"/>
      </geometry>
      <origin rpy="0 0 0" xyz="-0.0 0.0 0"/>
      <material name="Gazebo/Grey"/>
    </visual>
    <collision>
      <geometry>
        <cylinder length="0.02" radius="0.005"/>
      </geometry>
      <origin rpy="0 0 0" xyz="-0.0 0.0 0"/>
    </collision>
    <inertial>
      <mass value="0.001"/>
      <inertia ixx="1.9791666666666667e-07" ixy="0" ixz="0" iyy="1.9791666666666667e-07" iyz="0" izz="6.250000000000001e-08"/>
      <origin rpy="0 0 0" xyz="-0.0 0.0 0"/>
    </inertial>
  </link>
  <joint name="joint_tether_9" type="continuous">
    <origin rpy="0.0 0.0 0.0" xyz="0.0 0.0 0.02"/>
    <axis xyz="0 1 1"/>
    <!-- TODO(ff): not currently set because it's not yet supported -->
    <!-- <limit effort="2000" velocity="${max_rot_velocity}" /> -->
    <parent link="tether/link_08"/>
    <child link="tether/link_09"/>
  </joint>
  <link name="tether/link_10">
    <visual>
      <geometry>
        <cylinder length="0.02" radius="0.005"/>
      </geometry>
      <origin rpy="0 0 0" xyz="-0.0 0.0 0"/>
      <material name="Gazebo/Grey"/>
    </visual>
    <collision>
      <geometry>
        <cylinder length="0.02" radius="0.005"/>
      </geometry>
      <origin rpy="0 0 0" xyz="-0.0 0.0 0"/>
    </collision>
    <inertial>
      <mass value="0.001"/>
      <inertia ixx="1.9791666666666667e-07" ixy="0" ixz="0" iyy="1.9791666666666667e-07" iyz="0" izz="6.250000000000001e-08"/>
      <origin rpy="0 0 0" xyz="-0.0 0.0 0"/>
    </inertial>
  </link>
  <joint name="joint_tether_10" type="continuous">
    <origin rpy="0.0 0.0 0.0" xyz="0.0 0.0 0.02"/>
    <axis xyz="0 1 1"/>
    <!-- TODO(ff): not currently set because it's not yet supported -->
    <!-- <limit effort="2000" velocity="${max_rot_velocity}" /> -->
    <parent link="tether/link_09"/>
    <child link="tether/link_10"/>
  </joint>
  <link name="tether/link_11">
    <visual>
      <geometry>
        <cylinder length="0.02" radius="0.005"/>
      </geometry>
      <origin rpy="0 0 0" xyz="-0.0 0.0 0"/>
      <material name="Gazebo/Grey"/>
    </visual>
    <collision>
      <geometry>
        <cylinder length="0.02" radius="0.005"/>
      </geometry>
      <origin rpy="0 0 0" xyz="-0.0 0.0 0"/>
    </collision>
    <inertial>
      <mass value="0.001"/>
      <inertia ixx="1.9791666666666667e-07" ixy="0" ixz="0" iyy="1.9791666666666667e-07" iyz="0" izz="6.250000000000001e-08"/>
      <origin rpy="0 0 0" xyz="-0.0 0.0 0"/>
    </inertial>
  </link>
  <joint name="joint_tether_11" type="continuous">
    <origin rpy="0.0 0.0 0.0" xyz="0.0 0.0 0.02"/>
    <axis xyz="0 1 1"/>
    <!-- TODO(ff): not currently set because it's not yet supported -->
    <!-- <limit effort="2000" velocity="${max_rot_velocity}" /> -->
    <parent link="tether/link_10"/>
    <child link="tether/link_11"/>
  </joint>
  <link name="tether/link_12">
    <visual>
      <geometry>
        <cylinder length="0.02" radius="0.005"/>
      </geometry>
      <origin rpy="0 0 0" xyz="-0.0 0.0 0"/>
      <material name="Gazebo/Grey"/>
    </visual>
    <collision>
      <geometry>
        <cylinder length="0.02" radius="0.005"/>
      </geometry>
      <origin rpy="0 0 0" xyz="-0.0 0.0 0"/>
    </collision>
    <inertial>
      <mass value="0.001"/>
      <inertia ixx="1.9791666666666667e-07" ixy="0" ixz="0" iyy="1.9791666666666667e-07" iyz="0" izz="6.250000000000001e-08"/>
      <origin rpy="0 0 0" xyz="-0.0 0.0 0"/>
    </inertial>
  </link>
  <joint name="joint_tether_12" type="continuous">
    <origin rpy="0.0 0.0 0.0" xyz="0.0 0.0 0.02"/>
    <axis xyz="0 1 1"/>
    <!-- TODO(ff): not currently set because it's not yet supported -->
    <!-- <limit effort="2000" velocity="${max_rot_velocity}" /> -->
    <parent link="tether/link_11"/>
    <child link="tether/link_12"/>
  </joint>
  <link name="tether/link_13">
    <visual>
      <geometry>
        <cylinder length="0.02" radius="0.005"/>
      </geometry>
      <origin rpy="0 0 0" xyz="-0.0 0.0 0"/>
      <material name="Gazebo/Grey"/>
    </visual>
    <collision>
      <geometry>
        <cylinder length="0.02" radius="0.005"/>
      </geometry>
      <origin rpy="0 0 0" xyz="-0.0 0.0 0"/>
    </collision>
    <inertial>
      <mass value="0.001"/>
      <inertia ixx="1.9791666666666667e-07" ixy="0" ixz="0" iyy="1.9791666666666667e-07" iyz="0" izz="6.250000000000001e-08"/>
      <origin rpy="0 0 0" xyz="-0.0 0.0 0"/>
    </inertial>
  </link>
  <joint name="joint_tether_13" type="continuous">
    <origin rpy="0.0 0.0 0.0" xyz="0.0 0.0 0.02"/>
    <axis xyz="0 1 1"/>
    <!-- TODO(ff): not currently set because it's not yet supported -->
    <!-- <limit effort="2000" velocity="${max_rot_velocity}" /> -->
    <parent link="tether/link_12"/>
    <child link="tether/link_13"/>
  </joint>
  <link name="tether/link_14">
    <visual>
      <geometry>
        <cylinder length="0.02" radius="0.005"/>
      </geometry>
      <origin rpy="0 0 0" xyz="-0.0 0.0 0"/>
      <material name="Gazebo/Grey"/>
    </visual>
    <collision>
      <geometry>
        <cylinder length="0.02" radius="0.005"/>
      </geometry>
      <origin rpy="0 0 0" xyz="-0.0 0.0 0"/>
    </collision>
    <inertial>
      <mass value="0.001"/>
      <inertia ixx="1.9791666666666667e-07" ixy="0" ixz="0" iyy="1.9791666666666667e-07" iyz="0" izz="6.250000000000001e-08"/>
      <origin rpy="0 0 0" xyz="-0.0 0.0 0"/>
    </inertial>
  </link>
  <joint name="joint_tether_14" type="continuous">
    <origin rpy="0.0 0.0 0.0" xyz="0.0 0.0 0.02"/>
    <axis xyz="0 1 1"/>
    <!-- TODO(ff): not currently set because it's not yet supported -->
    <!-- <limit effort="2000" velocity="${max_rot_velocity}" /> -->
    <parent link="tether/link_13"/>
    <child link="tether/link_14"/>
  </joint>
  <link name="tether/link_15">
    <visual>
      <geometry>
        <cylinder length="0.02" radius="0.005"/>
      </geometry>
      <origin rpy="0 0 0" xyz="-0.0 0.0 0"/>
      <material name="Gazebo/Grey"/>
    </visual>
    <collision>
      <geometry>
        <cylinder length="0.02" radius="0.005"/>
      </geometry>
      <origin rpy="0 0 0" xyz="-0.0 0.0 0"/>
    </collision>
    <inertial>
      <mass value="0.001"/>
      <inertia ixx="1.9791666666666667e-07" ixy="0" ixz="0" iyy="1.9791666666666667e-07" iyz="0" izz="6.250000000000001e-08"/>
      <origin rpy="0 0 0" xyz="-0.0 0.0 0"/>
    </inertial>
  </link>
  <joint name="joint_tether_15" type="continuous">
    <origin rpy="0.0 0.0 0.0" xyz="0.0 0.0 0.02"/>
    <axis xyz="0 1 1"/>
    <!-- TODO(ff): not currently set because it's not yet supported -->
    <!-- <limit effort="2000" velocity="${max_rot_velocity}" /> -->
    <parent link="tether/link_14"/>
    <child link="tether/link_15"/>
  </joint>

  <link name="tether/link_16">
    <visual>
      <geometry>
        <cylinder length="0.02" radius="0.005"/>
      </geometry>
      <origin rpy="0 0 0" xyz="-0.0 0.0 0"/>
      <material name="Gazebo/Grey"/>
    </visual>
    <collision>
      <geometry>
        <cylinder length="0.02" radius="0.005"/>
      </geometry>
      <origin rpy="0 0 0" xyz="-0.0 0.0 0"/>
    </collision>
    <inertial>
      <mass value="0.001"/>
      <inertia ixx="1.9791666666666667e-07" ixy="0" ixz="0" iyy="1.9791666666666667e-07" iyz="0" izz="6.250000000000001e-08"/>
      <origin rpy="0 0 0" xyz="-0.0 0.0 0"/>
    </inertial>
  </link>
  <joint name="joint_tether_16" type="continuous">
    <origin rpy="0.0 0.0 0.0" xyz="0.0 0.0 0.02"/>
    <axis xyz="0 1 1"/>
    <!-- TODO(ff): not currently set because it's not yet supported -->
    <!-- <limit effort="2000" velocity="${max_rot_velocity}" /> -->
    <parent link="tether/link_15"/>
    <child link="tether/link_16"/>
  </joint>
  <link name="tether/link_17">
    <visual>
      <geometry>
        <cylinder length="0.02" radius="0.005"/>
      </geometry>
      <origin rpy="0 0 0" xyz="-0.0 0.0 0"/>
      <material name="Gazebo/Grey"/>
    </visual>
    <collision>
      <geometry>
        <cylinder length="0.02" radius="0.005"/>
      </geometry>
      <origin rpy="0 0 0" xyz="-0.0 0.0 0"/>
    </collision>
    <inertial>
      <mass value="0.001"/>
      <inertia ixx="1.9791666666666667e-07" ixy="0" ixz="0" iyy="1.9791666666666667e-07" iyz="0" izz="6.250000000000001e-08"/>
      <origin rpy="0 0 0" xyz="-0.0 0.0 0"/>
    </inertial>
  </link>
  <joint name="joint_tether_17" type="continuous">
    <origin rpy="0.0 0.0 0.0" xyz="0.0 0.0 0.02"/>
    <axis xyz="0 1 1"/>
    <!-- TODO(ff): not currently set because it's not yet supported -->
    <!-- <limit effort="2000" velocity="${max_rot_velocity}" /> -->
    <parent link="tether/link_16"/>
    <child link="tether/link_17"/>
  </joint>
  <link name="tether/link_18">
    <visual>
      <geometry>
        <cylinder length="0.02" radius="0.005"/>
      </geometry>
      <origin rpy="0 0 0" xyz="-0.0 0.0 0"/>
      <material name="Gazebo/Grey"/>
    </visual>
    <collision>
      <geometry>
        <cylinder length="0.02" radius="0.005"/>
      </geometry>
      <origin rpy="0 0 0" xyz="-0.0 0.0 0"/>
    </collision>
    <inertial>
      <mass value="0.001"/>
      <inertia ixx="1.9791666666666667e-07" ixy="0" ixz="0" iyy="1.9791666666666667e-07" iyz="0" izz="6.250000000000001e-08"/>
      <origin rpy="0 0 0" xyz="-0.0 0.0 0"/>
    </inertial>
  </link>
  <joint name="joint_tether_18" type="continuous">
    <origin rpy="0.0 0.0 0.0" xyz="0.0 0.0 0.02"/>
    <axis xyz="0 1 1"/>
    <!-- TODO(ff): not currently set because it's not yet supported -->
    <!-- <limit effort="2000" velocity="${max_rot_velocity}" /> -->
    <parent link="tether/link_17"/>
    <child link="tether/link_18"/>
  </joint>
  <link name="tether/link_19">
    <visual>
      <geometry>
        <cylinder length="0.02" radius="0.005"/>
      </geometry>
      <origin rpy="0 0 0" xyz="-0.0 0.0 0"/>
      <material name="Gazebo/Grey"/>
    </visual>
    <collision>
      <geometry>
        <cylinder length="0.02" radius="0.005"/>
      </geometry>
      <origin rpy="0 0 0" xyz="-0.0 0.0 0"/>
    </collision>
    <inertial>
      <mass value="0.001"/>
      <inertia ixx="1.9791666666666667e-07" ixy="0" ixz="0" iyy="1.9791666666666667e-07" iyz="0" izz="6.250000000000001e-08"/>
      <origin rpy="0 0 0" xyz="-0.0 0.0 0"/>
    </inertial>
  </link>
  <joint name="joint_tether_19" type="continuous">
    <origin rpy="0.0 0.0 0.0" xyz="0.0 0.0 0.02"/>
    <axis xyz="0 1 1"/>
    <!-- TODO(ff): not currently set because it's not yet supported -->
    <!-- <limit effort="2000" velocity="${max_rot_velocity}" /> -->
    <parent link="tether/link_18"/>
    <child link="tether/link_19"/>
  </joint>
  
  <link name="tether/link_20">
    <visual>
      <geometry>
        <cylinder length="0.02" radius="0.005"/>
      </geometry>
      <origin rpy="0 0 0" xyz="-0.0 0.0 0"/>
      <material name="Gazebo/Grey"/>
    </visual>
    <collision>
      <geometry>
        <cylinder length="0.02" radius="0.005"/>
      </geometry>
      <origin rpy="0 0 0" xyz="-0.0 0.0 0"/>
    </collision>
    <inertial>
      <mass value="0.001"/>
      <inertia ixx="1.9791666666666667e-07" ixy="0" ixz="0" iyy="1.9791666666666667e-07" iyz="0" izz="6.250000000000001e-08"/>
      <origin rpy="0 0 0" xyz="-0.0 0.0 0"/>
    </inertial>
  </link>
  <joint name="joint_tether_20" type="continuous">
    <origin rpy="0.0 0.0 0.0" xyz="0.0 0.0 0.02"/>
    <axis xyz="0 1 1"/>
    <!-- TODO(ff): not currently set because it's not yet supported -->
    <!-- <limit effort="2000" velocity="${max_rot_velocity}" /> -->
    <parent link="tether/link_19"/>
    <child link="tether/link_20"/>
  </joint>

  <gazebo>
    <plugin filename="libgazebo_ros_modelate_tether.so" name="gazebo_ros_modelate_tether">
      <namespace>marsupial_tether</namespace>
      <numLinkTether>20</numLinkTether>
      <nameLinkFrame>link_tether</nameLinkFrame>
      <initLengthTether>0.5</initLengthTether>  <!-- Initial Tether length given by distance between UGV and UAV -->
    </plugin>
  </gazebo>

</robot>

