<?xml version="1.0" ?>

<sdf version='1.6'>
  <model name='x4'>
  <pose>0 0 0.121078 0 0 0</pose>
    <link name='x4/base_link'>
      <pose frame=''>0 0 0 0 -0 0</pose>
      <inertial>
        <pose frame=''>0 0 0 0 -0 0</pose>
        <mass>3.42</mass>
        <inertia>
          <ixx>0.075</ixx>
          <ixy>0</ixy>
          <ixz>0</ixz>
          <iyy>0.075</iyy>
          <iyz>0</iyz>
          <izz>0.148916</izz>
        </inertia>
      </inertial>
      <collision name='x4/base_link_inertia_collision'>
        <pose frame=''>0 0 0 0 -0 0</pose>
        <geometry>
          <box>
            <size>0.3 0.3 0.25</size>
          </box>
        </geometry>
      </collision>
      <visual name='x4/base_link_inertia_visual'>
        <pose frame=''>0 0 0 0 -0 0</pose>
        <geometry>
          <mesh>
            <scale>1 1 1</scale>
            <uri>model://x4/meshes/x4.dae</uri>
          </mesh>
        </geometry>
      </visual>
    </link>
    <link name='x4/rotor_0'>
      <pose frame=''>0.247 0.1506 0.028 0.087267 0 0.523599</pose>
      <inertial>
        <pose frame=''>0 0 0 0 -0 0</pose>
        <mass>0.005</mass>
        <inertia>
          <ixx>9.75e-07</ixx>
          <ixy>0</ixy>
          <ixz>0</ixz>
          <iyy>8.13545e-05</iyy>
          <iyz>0</iyz>
          <izz>8.22545e-05</izz>
        </inertia>
      </inertial>
      <collision name='x4/rotor_0_collision'>
        <pose frame=''>0 0 0 0 -0 0</pose>
        <geometry>
          <cylinder>
            <length>0.005</length>
            <radius>0.1397</radius>
          </cylinder>
        </geometry>
        <surface>
          <contact>
            <ode/>
          </contact>
          <friction>
            <ode/>
          </friction>
        </surface>
      </collision>
      <visual name='x4/rotor_0_visual'>
        <pose frame=''>0 0 0 0 -0 0</pose>
        <geometry>
          <mesh>
            <scale>1 1 1</scale>
            <uri>model://x4/meshes/neo11_propeller_ccw.dae</uri>
          </mesh>
        </geometry>
        <material>
          <script>
            <name>Gazebo/Red</name>
            <uri>file://media/materials/scripts/gazebo.material</uri>
          </script>
        </material>
      </visual>
      <gravity>1</gravity>
      <velocity_decay/>
    </link>
    <joint name='x4/rotor_0_joint' type='revolute'>
      <child>x4/rotor_0</child>
      <parent>x4/base_link</parent>
      <axis>
        <xyz>0.043578 -0.075479 0.996195</xyz>
        <limit>
          <lower>-1e+16</lower>
          <upper>1e+16</upper>
        </limit>
        <dynamics>
          <spring_reference>0</spring_reference>
          <spring_stiffness>0</spring_stiffness>
        </dynamics>
        <use_parent_model_frame>1</use_parent_model_frame>
      </axis>
    </joint>
    <link name='x4/rotor_1'>
      <pose frame=''>-0.00067 0.28929 0.028 0 -0.087267 0</pose>
      <inertial>
        <pose frame=''>0 0 0 0 -0 0</pose>
        <mass>0.005</mass>
        <inertia>
          <ixx>9.75e-07</ixx>
          <ixy>0</ixy>
          <ixz>0</ixz>
          <iyy>8.13545e-05</iyy>
          <iyz>0</iyz>
          <izz>8.22545e-05</izz>
        </inertia>
      </inertial>
      <collision name='x4/rotor_1_collision'>
        <pose frame=''>0 0 0 0 -0 0</pose>
        <geometry>
          <cylinder>
            <length>0.005</length>
            <radius>0.1397</radius>
          </cylinder>
        </geometry>
        <surface>
          <contact>
            <ode/>
          </contact>
          <friction>
            <ode/>
          </friction>
        </surface>
      </collision>
      <visual name='x4/rotor_1_visual'>
        <pose frame=''>0 0 0 0 -0 0</pose>
        <geometry>
          <mesh>
            <scale>1 1 1</scale>
            <uri>model://x4/meshes/neo11_propeller_cw.dae</uri>
          </mesh>
        </geometry>
        <material>
          <script>
            <name>Gazebo/Blue</name>
            <uri>file://media/materials/scripts/gazebo.material</uri>
          </script>
        </material>
      </visual>
      <gravity>1</gravity>
      <velocity_decay/>
    </link>
    <joint name='x4/rotor_1_joint' type='revolute'>
      <child>x4/rotor_1</child>
      <parent>x4/base_link</parent>
      <axis>
        <xyz>-0.087156 0 0.996195</xyz>
        <limit>
          <lower>-1e+16</lower>
          <upper>1e+16</upper>
        </limit>
        <dynamics>
          <spring_reference>0</spring_reference>
          <spring_stiffness>0</spring_stiffness>
        </dynamics>
        <use_parent_model_frame>1</use_parent_model_frame>
      </axis>
    </joint>
    <link name='x4/rotor_2'>
      <pose frame=''>-0.2501 0.1454 0.028 0.087267 -0 2.61799</pose>
      <inertial>
        <pose frame=''>0 0 0 0 -0 0</pose>
        <mass>0.005</mass>
        <inertia>
          <ixx>9.75e-07</ixx>
          <ixy>0</ixy>
          <ixz>0</ixz>
          <iyy>8.13545e-05</iyy>
          <iyz>0</iyz>
          <izz>8.22545e-05</izz>
        </inertia>
      </inertial>
      <collision name='x4/rotor_2_collision'>
        <pose frame=''>0 0 0 0 -0 0</pose>
        <geometry>
          <cylinder>
            <length>0.005</length>
            <radius>0.1397</radius>
          </cylinder>
        </geometry>
        <surface>
          <contact>
            <ode/>
          </contact>
          <friction>
            <ode/>
          </friction>
        </surface>
      </collision>
      <visual name='x4/rotor_2_visual'>
        <pose frame=''>0 0 0 0 -0 0</pose>
        <geometry>
          <mesh>
            <scale>1 1 1</scale>
            <uri>model://x4/meshes/neo11_propeller_ccw.dae</uri>
          </mesh>
        </geometry>
        <material>
          <script>
            <name>Gazebo/Blue</name>
            <uri>file://media/materials/scripts/gazebo.material</uri>
          </script>
        </material>
      </visual>
      <gravity>1</gravity>
      <velocity_decay/>
    </link>
    <joint name='x4/rotor_2_joint' type='revolute'>
      <child>x4/rotor_2</child>
      <parent>x4/base_link</parent>
      <axis>
        <xyz>0.043578 0.075479 0.996195</xyz>
        <limit>
          <lower>-1e+16</lower>
          <upper>1e+16</upper>
        </limit>
        <dynamics>
          <spring_reference>0</spring_reference>
          <spring_stiffness>0</spring_stiffness>
        </dynamics>
        <use_parent_model_frame>1</use_parent_model_frame>
      </axis>
    </joint>
    <link name='x4/rotor_3'>
      <pose frame=''>-0.2501 -0.1454 0.028 -0.087267 -0 -2.61799</pose>
      <inertial>
        <pose frame=''>0 0 0 0 -0 0</pose>
        <mass>0.005</mass>
        <inertia>
          <ixx>9.75e-07</ixx>
          <ixy>0</ixy>
          <ixz>0</ixz>
          <iyy>8.13545e-05</iyy>
          <iyz>0</iyz>
          <izz>8.22545e-05</izz>
        </inertia>
      </inertial>
      <collision name='x4/rotor_3_collision'>
        <pose frame=''>0 0 0 0 -0 0</pose>
        <geometry>
          <cylinder>
            <length>0.005</length>
            <radius>0.1397</radius>
          </cylinder>
        </geometry>
        <surface>
          <contact>
            <ode/>
          </contact>
          <friction>
            <ode/>
          </friction>
        </surface>
      </collision>
      <visual name='x4/rotor_3_visual'>
        <pose frame=''>0 0 0 0 -0 0</pose>
        <geometry>
          <mesh>
            <scale>1 1 1</scale>
            <uri>model://x4/meshes/neo11_propeller_cw.dae</uri>
          </mesh>
        </geometry>
        <material>
          <script>
            <name>Gazebo/Blue</name>
            <uri>file://media/materials/scripts/gazebo.material</uri>
          </script>
        </material>
      </visual>
      <gravity>1</gravity>
      <velocity_decay/>
    </link>
    <joint name='x4/rotor_3_joint' type='revolute'>
      <child>x4/rotor_3</child>
      <parent>x4/base_link</parent>
      <axis>
        <xyz>0.043578 -0.075479 0.996195</xyz>
        <limit>
          <lower>-1e+16</lower>
          <upper>1e+16</upper>
        </limit>
        <dynamics>
          <spring_reference>0</spring_reference>
          <spring_stiffness>0</spring_stiffness>
        </dynamics>
        <use_parent_model_frame>1</use_parent_model_frame>
      </axis>
    </joint>
    <link name='x4/rotor_4'>
      <pose frame=''>-0.00067 -0.28929 0.028 -0 0.087267 -3.14159</pose>
      <inertial>
        <pose frame=''>0 0 0 0 -0 0</pose>
        <mass>0.005</mass>
        <inertia>
          <ixx>9.75e-07</ixx>
          <ixy>0</ixy>
          <ixz>0</ixz>
          <iyy>8.13545e-05</iyy>
          <iyz>0</iyz>
          <izz>8.22545e-05</izz>
        </inertia>
      </inertial>
      <collision name='x4/rotor_4_collision'>
        <pose frame=''>0 0 0 0 -0 0</pose>
        <geometry>
          <cylinder>
            <length>0.005</length>
            <radius>0.1397</radius>
          </cylinder>
        </geometry>
        <surface>
          <contact>
            <ode/>
          </contact>
          <friction>
            <ode/>
          </friction>
        </surface>
      </collision>
      <visual name='x4/rotor_4_visual'>
        <pose frame=''>0 0 0 0 -0 0</pose>
        <geometry>
          <mesh>
            <scale>1 1 1</scale>
            <uri>model://x4/meshes/neo11_propeller_ccw.dae</uri>
          </mesh>
        </geometry>
        <material>
          <script>
            <name>Gazebo/Blue</name>
            <uri>file://media/materials/scripts/gazebo.material</uri>
          </script>
        </material>
      </visual>
      <gravity>1</gravity>
      <velocity_decay/>
    </link>
    <joint name='x4/rotor_4_joint' type='revolute'>
      <child>x4/rotor_4</child>
      <parent>x4/base_link</parent>
      <axis>
        <xyz>-0.087156 -0 0.996195</xyz>
        <limit>
          <lower>-1e+16</lower>
          <upper>1e+16</upper>
        </limit>
        <dynamics>
          <spring_reference>0</spring_reference>
          <spring_stiffness>0</spring_stiffness>
        </dynamics>
        <use_parent_model_frame>1</use_parent_model_frame>
      </axis>
    </joint>
    <link name='x4/rotor_5'>
      <pose frame=''>0.247 -0.1506 0.028 -0.087267 0 -0.523599</pose>
      <inertial>
        <pose frame=''>0 0 0 0 -0 0</pose>
        <mass>0.005</mass>
        <inertia>
          <ixx>9.75e-07</ixx>
          <ixy>0</ixy>
          <ixz>0</ixz>
          <iyy>8.13545e-05</iyy>
          <iyz>0</iyz>
          <izz>8.22545e-05</izz>
        </inertia>
      </inertial>
      <collision name='x4/rotor_5_collision'>
        <pose frame=''>0 0 0 0 -0 0</pose>
        <geometry>
          <cylinder>
            <length>0.005</length>
            <radius>0.1397</radius>
          </cylinder>
        </geometry>
        <surface>
          <contact>
            <ode/>
          </contact>
          <friction>
            <ode/>
          </friction>
        </surface>
      </collision>
      <visual name='x4/rotor_5_visual'>
        <pose frame=''>0 0 0 0 -0 0</pose>
        <geometry>
          <mesh>
            <scale>1 1 1</scale>
            <uri>model://x4/meshes/neo11_propeller_cw.dae</uri>
          </mesh>
        </geometry>
        <material>
          <script>
            <name>Gazebo/Red</name>
            <uri>file://media/materials/scripts/gazebo.material</uri>
          </script>
        </material>
      </visual>
      <gravity>1</gravity>
      <velocity_decay/>
    </link>
    <joint name='x4/rotor_5_joint' type='revolute'>
      <child>x4/rotor_5</child>
      <parent>x4/base_link</parent>
      <axis>
        <xyz>0.043578 0.075479 0.996195</xyz>
        <limit>
          <lower>-1e+16</lower>
          <upper>1e+16</upper>
        </limit>
        <dynamics>
          <spring_reference>0</spring_reference>
          <spring_stiffness>0</spring_stiffness>
        </dynamics>
        <use_parent_model_frame>1</use_parent_model_frame>
      </axis>
    </joint>

    <plugin filename="ignition-gazebo-multicopter-motor-model-system"
        name="ignition::gazebo::systems::MulticopterMotorModel">
        <robotNamespace>x4</robotNamespace>
        <jointName>rotor_0_joint</jointName>
        <linkName>x4/rotor_0</linkName>
        <turningDirection>ccw</turningDirection>
        <timeConstantUp>0.0182</timeConstantUp>
        <timeConstantDown>0.0182</timeConstantDown>
        <maxRotVelocity>1000.0</maxRotVelocity>
        <motorConstant>1.269e-05</motorConstant>
        <momentConstant>0.016754</momentConstant>
        <commandSubTopic>command/motor_speed</commandSubTopic>
        <motorNumber>0</motorNumber>
        <rotorDragCoefficient>2.0673e-04</rotorDragCoefficient>
        <rotorDragCoefficient>0</rotorDragCoefficient>
        <rollingMomentCoefficient>0</rollingMomentCoefficient>
        <motorSpeedPubTopic>motor_speed/0</motorSpeedPubTopic>
        <rotorVelocitySlowdownSim>2</rotorVelocitySlowdownSim>
        <motorType>velocity</motorType>
      </plugin>
      <plugin filename="ignition-gazebo-multicopter-motor-model-system"
        name="ignition::gazebo::systems::MulticopterMotorModel">
        <robotNamespace>x4</robotNamespace>
        <jointName>rotor_1_joint</jointName>
        <linkName>x4/rotor_1</linkName>
        <turningDirection>cw</turningDirection>
        <timeConstantUp>0.0182</timeConstantUp>
        <timeConstantDown>0.0182</timeConstantDown>
        <maxRotVelocity>1000.0</maxRotVelocity>
        <motorConstant>1.269e-05</motorConstant>
        <momentConstant>0.016754</momentConstant>
        <commandSubTopic>command/motor_speed</commandSubTopic>
        <motorNumber>1</motorNumber>
        <rotorDragCoefficient>2.0673e-04</rotorDragCoefficient>
        <rotorDragCoefficient>0</rotorDragCoefficient>
        <rollingMomentCoefficient>0</rollingMomentCoefficient>
        <motorSpeedPubTopic>motor_speed/1</motorSpeedPubTopic>
        <rotorVelocitySlowdownSim>2</rotorVelocitySlowdownSim>
        <motorType>velocity</motorType>
      </plugin>
      <plugin filename="ignition-gazebo-multicopter-motor-model-system"
        name="ignition::gazebo::systems::MulticopterMotorModel">
        <robotNamespace>x4</robotNamespace>
        <jointName>rotor_2_joint</jointName>
        <linkName>x4/rotor_2</linkName>
        <turningDirection>ccw</turningDirection>
        <timeConstantUp>0.0182</timeConstantUp>
        <timeConstantDown>0.0182</timeConstantDown>
        <maxRotVelocity>1000.0</maxRotVelocity>
        <motorConstant>1.269e-05</motorConstant>
        <momentConstant>0.016754</momentConstant>
        <commandSubTopic>command/motor_speed</commandSubTopic>
        <motorNumber>2</motorNumber>
        <rotorDragCoefficient>2.0673e-04</rotorDragCoefficient>
        <rotorDragCoefficient>0</rotorDragCoefficient>
        <rollingMomentCoefficient>0</rollingMomentCoefficient>
        <motorSpeedPubTopic>motor_speed/2</motorSpeedPubTopic>
        <rotorVelocitySlowdownSim>2</rotorVelocitySlowdownSim>
        <motorType>velocity</motorType>
      </plugin>
      <plugin filename="ignition-gazebo-multicopter-motor-model-system"
        name="ignition::gazebo::systems::MulticopterMotorModel">
        <robotNamespace>x4</robotNamespace>
        <jointName>rotor_3_joint</jointName>
        <linkName>x4/rotor_3</linkName>
        <turningDirection>cw</turningDirection>
        <timeConstantUp>0.0182</timeConstantUp>
        <timeConstantDown>0.0182</timeConstantDown>
        <maxRotVelocity>1000.0</maxRotVelocity>
        <motorConstant>1.269e-05</motorConstant>
        <momentConstant>0.016754</momentConstant>
        <commandSubTopic>command/motor_speed</commandSubTopic>
        <motorNumber>3</motorNumber>
        <rotorDragCoefficient>2.0673e-04</rotorDragCoefficient>
        <rotorDragCoefficient>0</rotorDragCoefficient>
        <rollingMomentCoefficient>0</rollingMomentCoefficient>
        <motorSpeedPubTopic>motor_speed/3</motorSpeedPubTopic>
        <rotorVelocitySlowdownSim>2</rotorVelocitySlowdownSim>
        <motorType>velocity</motorType>
      </plugin>
      <plugin filename="ignition-gazebo-multicopter-motor-model-system"
        name="ignition::gazebo::systems::MulticopterMotorModel">
        <robotNamespace>x4</robotNamespace>
        <jointName>rotor_4_joint</jointName>
        <linkName>x4/rotor_4</linkName>
        <turningDirection>ccw</turningDirection>
        <timeConstantUp>0.0182</timeConstantUp>
        <timeConstantDown>0.0182</timeConstantDown>
        <maxRotVelocity>1000.0</maxRotVelocity>
        <motorConstant>1.269e-05</motorConstant>
        <momentConstant>0.016754</momentConstant>
        <commandSubTopic>command/motor_speed</commandSubTopic>
        <motorNumber>4</motorNumber>
        <rotorDragCoefficient>2.0673e-04</rotorDragCoefficient>
        <rotorDragCoefficient>0</rotorDragCoefficient>
        <rollingMomentCoefficient>0</rollingMomentCoefficient>
        <motorSpeedPubTopic>motor_speed/4</motorSpeedPubTopic>
        <rotorVelocitySlowdownSim>2</rotorVelocitySlowdownSim>
        <motorType>velocity</motorType>
      </plugin>
      <plugin filename="ignition-gazebo-multicopter-motor-model-system"
        name="ignition::gazebo::systems::MulticopterMotorModel">
        <robotNamespace>x4</robotNamespace>
        <jointName>rotor_5_joint</jointName>
        <linkName>x4/rotor_5</linkName>
        <turningDirection>cw</turningDirection>
        <timeConstantUp>0.0182</timeConstantUp>
        <timeConstantDown>0.0182</timeConstantDown>
        <maxRotVelocity>1000.0</maxRotVelocity>
        <motorConstant>1.269e-05</motorConstant>
        <momentConstant>0.016754</momentConstant>
        <commandSubTopic>command/motor_speed</commandSubTopic>
        <motorNumber>5</motorNumber>
        <rotorDragCoefficient>2.0673e-04</rotorDragCoefficient>
        <rotorDragCoefficient>0</rotorDragCoefficient>
        <rollingMomentCoefficient>0</rollingMomentCoefficient>
        <motorSpeedPubTopic>motor_speed/5</motorSpeedPubTopic>
        <rotorVelocitySlowdownSim>2</rotorVelocitySlowdownSim>
        <motorType>velocity</motorType>
      </plugin>

      <plugin
        filename="ignition-gazebo-multicopter-control-system"
        name="ignition::gazebo::systems::MulticopterVelocityControl">
        <robotNamespace>x4</robotNamespace>
        <commandSubTopic>gazebo/command/twist</commandSubTopic>
        <enableSubTopic>enable</enableSubTopic>
        <comLinkName>base_link</comLinkName>
        <velocityGain>6 6 10</velocityGain>
        <attitudeGain>4 4 2</attitudeGain>
        <angularRateGain>0.7 0.7 0.7</angularRateGain>
        <maximumLinearAcceleration>1 1 2</maximumLinearAcceleration>
        <maximumLinearVelocity>5 5 5</maximumLinearVelocity>
        <maximumAngularVelocity>3 3 3</maximumAngularVelocity>
        <linearVelocityNoiseMean>0 0 0</linearVelocityNoiseMean>
        <!-- linearVelocityNoiseStdDev based on error values reported in the paper Shen et. al., -->
        <!-- Vision-Based State Estimation and Trajectory Control Towards High-Speed Flight with a Quadrotor -->
        <!-- http://citeseerx.ist.psu.edu/viewdoc/download?doi=10.1.1.490.7958&rep=rep1&type=pdf -->
        <linearVelocityNoiseStdDev>0.1105 0.1261 0.0947</linearVelocityNoiseStdDev>
        <angularVelocityNoiseMean>0 0 0</angularVelocityNoiseMean>
        <!-- angularVelocityNoiseStdDev values based on ADIS16448's Rate Noise Density with a sample  -->
        <!-- time of 0.004 ms. -->
        <angularVelocityNoiseStdDev>0.004 0.004 0.004</angularVelocityNoiseStdDev>

        <rotorConfiguration>
          <rotor>
            <jointName>rotor_0_joint</jointName>
            <forceConstant>1.269e-05</forceConstant>
            <momentConstant>1.6754e-2</momentConstant>
            <direction>1</direction>
          </rotor>
          <rotor>
            <jointName>rotor_1_joint</jointName>
            <forceConstant>1.269e-05</forceConstant>
            <momentConstant>1.6754e-2</momentConstant>
            <direction>-1</direction>
          </rotor>
          <rotor>
            <jointName>rotor_2_joint</jointName>
            <forceConstant>1.269e-05</forceConstant>
            <momentConstant>1.6754e-2</momentConstant>
            <direction>1</direction>
          </rotor>
          <rotor>
            <jointName>rotor_3_joint</jointName>
            <forceConstant>1.269e-05</forceConstant>
            <momentConstant>1.6754e-2</momentConstant>
            <direction>-1</direction>
          </rotor>
          <rotor>
            <jointName>rotor_4_joint</jointName>
            <forceConstant>1.269e-05</forceConstant>
            <momentConstant>1.6754e-2</momentConstant>
            <direction>1</direction>
          </rotor>
          <rotor>
            <jointName>rotor_5_joint</jointName>
            <forceConstant>1.269e-05</forceConstant>
            <momentConstant>1.6754e-2</momentConstant>
            <direction>-1</direction>
          </rotor>
        </rotorConfiguration>
      </plugin>
      <plugin
        filename="ignition-gazebo-odometry-publisher-system"
        name="ignition::gazebo::systems::OdometryPublisher">
        <dimensions>3</dimensions>
      </plugin>
  </model>
</sdf>
