<?xml version='1.0'?>
<sdf version='1.7'>

  <odom_publish_frequency>1</odom_publish_frequency>
  <topic>cmd_vel</topic>

  <model name='arco'>
    <plugin filename="ignition-gazebo-imu-system"
      name="ignition::gazebo::systems::Imu">
    </plugin>
    <link name='base_link'>
      <inertial>
        <mass>20</mass>
        <inertia>
          <ixx>0.273333</ixx>
          <ixy>0</ixy>
          <ixz>0</ixz>
          <iyy>0.758667</iyy>
          <iyz>0</iyz>
          <izz>0.966667</izz>
        </inertia>
        <pose>0 0 0 0 -0 0</pose>
      </inertial>
      <pose>0 0 0 0 -0 0</pose>
      <visual name='visual'>
        <geometry>
          <box>
            <size>0.66 0.38 0.14</size>
          </box>
        </geometry>
        <material>
          <script>
            <name>Gazebo/Grey</name>
            <uri>file://media/materials/scripts/gazebo.material</uri>
          </script>
          <ambient>1 1 1 1</ambient>
          <diffuse>0.7 0.7 0.7 1</diffuse>
          <specular>0.01 0.01 0.01 1</specular>
          <emissive>0 0 0 1</emissive>
        </material>
      </visual>
      <collision name='collision'>
        <pose>0 0 0 0 -0 0</pose>
        <geometry>
          <box>
            <size>0.66 0.38 0.14</size>
          </box>
        </geometry>
      </collision>

      <collision name='imu_collision'>
        <pose>0.12 0 0.09 0 -0 0</pose>
        <geometry>
          <box>
            <size>0.031 0.031 0.01</size>
          </box>
        </geometry>
      </collision>
      <collision name='os1_sensor_collision'>
        <pose>0.2795 0 0.12 0 -0 0</pose>
        <geometry>
          <cylinder>
            <length>0.0717</length>
            <radius>0.0516</radius>
          </cylinder>
        </geometry>
      </collision>
      <visual name='imu_visual'>
        <pose>0.12 0 0.09 0 -0 0</pose>
        <geometry>
          <mesh>
            <scale>0.001 0.001 0.001</scale>
            <uri>model://arco/meshes/razor_imu/razor_imu.stl</uri>
          </mesh>
        </geometry>
        <material>
          <ambient>1 0 0  1</ambient>
          <diffuse>1 0 0 1</diffuse>
          <specular>1 0 0  1</specular>
          <emissive>0 0 0 1</emissive>
        </material>
      </visual>
      <sensor name="imu_sensor" type="imu">
        <always_on>1</always_on>
        <update_rate>1</update_rate>
        <visualize>true</visualize>
        <topic>imu</topic>
      </sensor>
    </link>

    <link name='front_right'>
      <inertial>
        <mass>0.5</mass>
        <inertia>
          <ixx>0.00104176</ixx>
          <ixy>0</ixy>
          <ixz>0</ixz>
          <iyy>0.00104176</iyy>
          <iyz>0</iyz>
          <izz>0.001225</izz>
        </inertia>
        <pose>0 0 0 0 -0 0</pose>
      </inertial>
      <pose>0.21 0.247 -0.06 1.57 0 0</pose>
      <visual name='visual'>
        <pose>0 0 0 1.57 -0 0</pose>
        <geometry>
          <mesh>
            <scale>0.002 0.002 0.002</scale>
            <uri>model://arco/meshes/mecanum/mecanum_wheel_left.STL</uri>
          </mesh> 
        </geometry>
        <material>
          <ambient>1 0 0  1</ambient>
          <diffuse>1 0.4 0 1</diffuse>
          <specular>1 0.4 0  1</specular>
          <emissive>0 0 0 1</emissive>
        </material>
      </visual>
      <collision name='collision'>
        <pose>0 0 0 0 -0 0</pose>
        <geometry>
          <cylinder>
            <radius>0.1015</radius>
            <length>0.07</length>
          </cylinder>
        </geometry>
      </collision>
    </link>

     <link name='rear_right'>
      <inertial>
        <mass>0.5</mass>
        <inertia>
          <ixx>0.00104176</ixx>
          <ixy>0</ixy>
          <ixz>0</ixz>
          <iyy>0.00104176</iyy>
          <iyz>0</iyz>
          <izz>0.001225</izz>
        </inertia>
        <pose>0 0 0 0 -0 0</pose>
      </inertial>
      <pose>-0.21 0.247 -0.06 1.57 -0 0</pose>
      <visual name='visual'>
        <pose>0 0 0 1.57 -0 0</pose>
        <geometry>
         <mesh>
            <scale>0.002 0.002 0.002</scale>
            <uri>model://arco/meshes/mecanum/mecanum_wheel_left.STL</uri>
          </mesh> 
        </geometry>
        <material>
          <ambient>1 0 0  1</ambient>
          <diffuse>1 0.4 0 1</diffuse>
          <specular>1 0.4 0  1</specular>
          <emissive>0 0 0 1</emissive>
        </material>
      </visual>
      <collision name='collision'>
        <pose>0 0 0 0 -0 0</pose>
        <geometry>
          <cylinder>
            <radius>0.1015</radius>
            <length>0.07</length>
          </cylinder>
        </geometry>
      </collision>
    </link>
     <link name='front_left'>
      <inertial>
        <mass>0.5</mass>
        <inertia>
          <ixx>0.00104176</ixx>
          <ixy>0</ixy>
          <ixz>0</ixz>
          <iyy>0.00104176</iyy>
          <iyz>0</iyz>
          <izz>0.001225</izz>
        </inertia>
        <pose>0 0 0 0 -0 0</pose>
      </inertial>
      <pose>0.21 -0.247 -0.06 1.57 -0 0</pose>
      <visual name='visual'>
        <pose>0 0 0 1.57 -0 0</pose>
        <geometry>
          <mesh>
            <scale>0.002 0.002 0.002</scale>
            <uri>model://arco/meshes/mecanum/mecanum_wheel_left.STL</uri>
          </mesh> 
        </geometry>
        <material>
          <ambient>1 0 0  1</ambient>
          <diffuse>1 0.4 0 1</diffuse>
          <specular>1 0.4 0  1</specular>
          <emissive>0 0 0 1</emissive>
        </material>
      </visual>
      <collision name='collision'>
        <pose>0 0 0 0 -0 0</pose>
        <geometry>
          <cylinder>
            <radius>0.1015</radius>
            <length>0.07</length>
          </cylinder>
        </geometry>
      </collision>
    </link>
    <link name='rear_left'>
      <inertial>
        <mass>0.5</mass>
        <inertia>
          <ixx>0.00104176</ixx>
          <ixy>0</ixy>
          <ixz>0</ixz>
          <iyy>0.00104176</iyy>
          <iyz>0</iyz>
          <izz>0.001225</izz>
        </inertia>
        <pose>0 0 0 1.57 -0 0</pose>
      </inertial>
      <pose>-0.21 -0.247 -0.06 1.57 -0 0</pose>
      <visual name='visual'>
        <pose>0 0 0 1.57 -0 0</pose>
        <geometry>
          <mesh>
            <scale>0.002 0.002 0.002</scale>
            <uri>model://arco/meshes/mecanum/mecanum_wheel_left.STL</uri>
          </mesh>
        </geometry>
        <material>
          <ambient>1 0 0  1</ambient>
          <diffuse>1 0.4 0 1</diffuse>
          <specular>1 0.4 0  1</specular>
          <emissive>0 0 0 1</emissive>
        </material>
      </visual>
      <collision name='collision'>
        <pose>0 0 0 0 -0 0</pose>
        <geometry>
          <cylinder>
            <radius>0.1015</radius>
            <length>0.07</length>
          </cylinder>
        </geometry>
      </collision>
    </link>

    <link name='base_cover'>
      <inertial>
        <mass>1</mass>
        <inertia>
          <ixx>0.0341417</ixx>
          <ixy>0</ixy>
          <ixz>0</ixz>
          <iyy>0.0363083</iyy>
          <iyz>0</iyz>
          <izz>0.0704333</izz>
        </inertia>
        <pose>0 0 0 0 -0 0</pose>
      </inertial>
      <pose>-0 0 0.075 0 -0 0</pose>
      <visual name='visual'>
        <geometry>
          <box>
            <size>0.66 0.64 0.01</size>
          </box>
        </geometry>
        <material>
          <ambient>1 1 1 1</ambient>
          <diffuse>0.7 0.7 0.7 1</diffuse>
          <specular>0.01 0.01 0.01 1</specular>
          <emissive>0 0 0 1</emissive>
        </material>
        <pose>0 0 0 0 -0 0</pose>
      </visual>
      <collision name='collision'>
        <pose>0 0 0 0 -0 0</pose>
        <geometry>
          <box>
            <size>0.66 0.64 0.01</size>
          </box>
        </geometry>
      </collision>
    </link>

    <link name='base_platform'>
      <inertial>
        <mass>10</mass>
        <inertia>
          <ixx>0.336333</ixx>
          <ixy>0</ixy>
          <ixz>0</ixz>
          <iyy>0.208333</iyy>
          <iyz>0</iyz>
          <izz>0.394667</izz>
        </inertia>
        <pose>0 0 0 0 -0 0</pose>
      </inertial>
      <pose>-0.1 -0 0.23 0 -0 0</pose>
      <visual name='visual'>
        <geometry>
          <box>
            <size>0.4 0.56 0.3</size>
          </box>
        </geometry>
        <material>
          <ambient>0.5 0.5 0.5 1</ambient>
          <diffuse>0.7 0.7 0.7 1</diffuse>
          <specular>0.01 0.01 0.01 1</specular>
          <emissive>0 0 0 1</emissive>
        </material>
      </visual>
      <collision name='collision'>
        <pose>0 0 0 0 -0 0</pose>
        <geometry>
          <box>
            <size>0.4 0.56 0.3</size>
          </box>
        </geometry>
      </collision>
    </link>

     <joint name='JOINT_fixed_1' type='fixed'>
      <parent>base_link</parent>
      <child>base_cover</child>
      <pose>0 0 0 0 -0 0</pose>
    </joint>

    <joint name='JOINT_fixed_2' type='fixed'>
      <parent>base_cover</parent>
      <child>base_platform</child>
      <pose>0 0 0 0 -0 0</pose>
    </joint>

    <joint name='JOINT_wheel_front_right' type='revolute'>
      <parent>base_link</parent>
      <child>front_right</child>
      <pose>0 0 0.035 0 -0 0</pose>
      <axis>
        <xyz>0 0 1</xyz>
        <limit>
          <lower>-1.79769e+308</lower>
          <upper>1.79769e+308</upper>
        </limit>
      </axis>
    </joint>

    <joint name='JOINT_wheel_rear_right' type='revolute'>
      <parent>base_link</parent>
      <child>rear_right</child>
      <pose>0 0 0.035 0 -0 0</pose>
      <axis>
        <xyz>0 0 1</xyz>
        <limit>
          <lower>-1.79769e+308</lower>
          <upper>1.79769e+308</upper>
        </limit>
      </axis>
    </joint>

    <joint name='JOINT_wheel_front_left' type='revolute'>
      <parent>base_link</parent>
      <child>front_left</child>
      <pose>0 0 -0.035 0 -0 0</pose>
      <axis>
        <xyz>0 0 1</xyz>
        <limit>
          <lower>-1.79769e+308</lower>
          <upper>1.79769e+308</upper>
        </limit>
      </axis>
    </joint>

    <joint name='JOINT_wheel_rear_left' type='revolute'>
      <parent>base_link</parent>
      <child>rear_left</child>
      <pose>0 0 -0.035 0 -0 0</pose>
      <axis>
        <xyz>0 0 1</xyz>
        <limit>
          <lower>-1.79769e+308</lower>
          <upper>1.79769e+308</upper>
        </limit>
      </axis>
    </joint>

    <!-- Track drive -->
      <plugin filename="ignition-gazebo-diff-drive-system"
              name="ignition::gazebo::systems::DiffDrive">
        <left_joint>JOINT_wheel_front_left</left_joint>
        <right_joint>JOINT_wheel_front_right</right_joint>
        <left_joint>JOINT_wheel_rear_left</left_joint>
        <right_joint>JOINT_wheel_rear_right</right_joint>
        <wheel_separation>0.42</wheel_separation>
        <wheel_radius>0.1015</wheel_radius>
        <odom_publish_frequency>100</odom_publish_frequency>
        <topic>idmind_motors/set_velocities</topic>
      </plugin>

  </model>
</sdf>