<?xml version="1.0"?>

<sdf version='1.7'>
  <model name='dji'>
  <static>false</static>

    <link name='base_link'>
      <pose>0 0 0 0 0 0</pose>
      <inertial>
        <pose>0 0 0 0 0 0</pose>
        <mass>1.5</mass>
        <!-- <inertia>
          <ixx>0.0347563</ixx>
          <ixy>0</ixy>
          <ixz>0</ixz>
          <iyy>0.0458929</iyy>
          <iyz>0</iyz>
          <izz>0.0977</izz>
        </inertia> -->
        <inertia>
          <ixx>0.00162</ixx>
          <ixy>0</ixy>
          <ixz>0</ixz>
          <iyy>0.00162</iyy>
          <iyz>0</iyz>
          <izz>0.0010125</izz>
        </inertia>
      </inertial>
      <collision name='base_link_inertia_collision'>
        <pose>0 0 0.014 0 0 0</pose>
        <geometry>
          <box>
            <size>0.4 0.4 0.4</size>
          </box>
        </geometry>
      </collision>
      <visual name='base_link_inertia_visual'>
        <pose>0 0 0 1.5707 0 1.5707</pose>
        <geometry>
          <mesh>
            <scale>1 1 1</scale>
            <uri>model://dji/meshes//m100.dae</uri>
          </mesh>
        </geometry>
        <material>
            <script>
              <uri>file://media/materials/scripts/gazebo.material</uri>
              <name>Gazebo/Grey</name>
            </script>
            <ambient>0.5 0.5 0.5 0.9</ambient>
        </material>
      </visual>
      <sensor name="os1_sensor" type="gpu_lidar">
        <topic>dji/os1_cloud_node</topic>
        <pose>0 0 0.0944 0 0 0</pose>
        <update_rate>20</update_rate>
        <lidar>
          <scan>
            <horizontal>
              <samples>1024</samples>
              <resolution>1</resolution>
              <min_angle>-3.14159</min_angle>
              <max_angle>3.14159</max_angle>
            </horizontal>
            <vertical>
              <samples>64</samples>
              <resolution>1</resolution>
              <min_angle>-0.785398163397</min_angle>
              <max_angle>0.785398163397</max_angle>
            </vertical>
          </scan>
          <range>
            <min>0.1</min>
            <max>50</max>
            <resolution>0.003</resolution>
          </range>
          <noise>
              <type>gaussian</type>
              <mean>0</mean>
              <stddev>0.03</stddev>
          </noise>
        </lidar>
      </sensor>
      <visual name='base_link_os1'>
        <pose>0 0 0.06 0 -0 1.5708</pose>
        <geometry>
          <mesh>
            <scale>1 1 1</scale>
            <uri>meshes/os1_64.dae</uri>
          </mesh>
        </geometry>
      </visual>
    </link>
    
    <link name='imu_link'>
      <pose>0 0 0 0 0 0</pose>
      <inertial>
        <pose>0 0 0 0 0 0</pose>
        <mass>0.015</mass>
        <inertia>
          <ixx>1e-05</ixx>
          <ixy>0</ixy>
          <ixz>0</ixz>
          <iyy>1e-05</iyy>
          <iyz>0</iyz>
          <izz>1e-05</izz>
        </inertia> 
      </inertial>
      <sensor name="imu_sensor" type="imu">
          <topic>dji/imu</topic>
          <always_on>1</always_on>
          <update_rate>250</update_rate>
              <imu>
                  <enable_orientation>0</enable_orientation>
                  <angular_velocity>
                      <x>
                          <noise type="gaussian">
                              <mean>0</mean>
                              <stddev>0.009</stddev>
                              <bias_mean>0.00075</bias_mean>
                              <bias_stddev>0.005</bias_stddev>
                              <dynamic_bias_stddev>0.00002</dynamic_bias_stddev>
                              <dynamic_bias_correlation_time>400.0</dynamic_bias_correlation_time>
                              <precision>0.00025</precision>
                          </noise>
                      </x>
                      <y>
                          <noise type="gaussian">
                              <mean>0</mean>
                              <stddev>0.009</stddev>
                              <bias_mean>0.00075</bias_mean>
                              <bias_stddev>0.005</bias_stddev>
                              <dynamic_bias_stddev>0.00002</dynamic_bias_stddev>
                              <dynamic_bias_correlation_time>400.0</dynamic_bias_correlation_time>
                              <precision>0.00025</precision>
                          </noise>
                      </y>
                      <z>
                          <noise type="gaussian">
                              <mean>0</mean>
                              <stddev>0.009</stddev>
                              <bias_mean>0.00075</bias_mean>
                              <bias_stddev>0.005</bias_stddev>
                              <dynamic_bias_stddev>0.00002</dynamic_bias_stddev>
                              <dynamic_bias_correlation_time>400.0</dynamic_bias_correlation_time>
                              <precision>0.00025</precision>
                          </noise>
                      </z>
                  </angular_velocity>
                  <linear_acceleration>
                      <x>
                          <noise type="gaussian">
                              <mean>0</mean>
                              <stddev>0.021</stddev>
                              <bias_mean>0.05</bias_mean>
                              <bias_stddev>0.0075</bias_stddev>
                              <dynamic_bias_stddev>0.000375</dynamic_bias_stddev>
                              <dynamic_bias_correlation_time>175.0</dynamic_bias_correlation_time>
                              <precision>0.005</precision>
                          </noise>
                      </x>
                      <y>
                          <noise type="gaussian">
                              <mean>0</mean>
                              <stddev>0.021</stddev>
                              <bias_mean>0.05</bias_mean>
                              <bias_stddev>0.0075</bias_stddev>
                              <dynamic_bias_stddev>0.000375</dynamic_bias_stddev>
                              <dynamic_bias_correlation_time>175.0</dynamic_bias_correlation_time>
                              <precision>0.005</precision>
                          </noise>
                      </y>
                      <z>
                          <noise type="gaussian">
                              <mean>0</mean>
                              <stddev>0.021</stddev>
                              <bias_mean>0.05</bias_mean>
                              <bias_stddev>0.0075</bias_stddev>
                              <dynamic_bias_stddev>0.000375</dynamic_bias_stddev>
                              <dynamic_bias_correlation_time>175.0</dynamic_bias_correlation_time>
                              <precision>0.005</precision>
                          </noise>
                      </z>
                  </linear_acceleration>
              </imu>
      </sensor>
    </link>

    <joint name='imu_joint' type='revolute'>
      <child>imu_link</child>
      <parent>base_link</parent>
      <axis>
        <xyz>1 0 0</xyz>
        <limit>
          <lower>0</lower>
          <upper>0</upper>
          <effort>0</effort>
          <velocity>0</velocity>
        </limit>
        <dynamics>
          <spring_reference>0</spring_reference>
          <spring_stiffness>0</spring_stiffness>
        </dynamics>
        <use_parent_model_frame>1</use_parent_model_frame>
      </axis>
    </joint>

    <link name='rotor_0'>
      <pose>0.232 -0.232 0.034 0 0 0</pose>
      <inertial>
        <pose>0 0 0 0 0 0</pose>
        <mass>0.005</mass>
        <inertia>
          <ixx>9.75e-07</ixx>
          <ixy>0</ixy>
          <ixz>0</ixz>
          <iyy>4.17041e-05</iyy>
          <iyz>0</iyz>
          <izz>4.26041e-05</izz>
        </inertia>
      </inertial>
      <collision name='rotor_0_collision'>
        <pose>0 0 0 0 0 0</pose>
        <geometry>
          <cylinder>
            <length>0.005</length>
            <radius>0.1</radius>
          </cylinder>
        </geometry>
        <surface>
          <contact>
            <ode/>
          </contact>
          <friction>
            <ode/>
          </friction>
        </surface>
      </collision>
      <visual name='rotor_0_visual'>
        <pose>0 0 0 0 0 0</pose>
        <geometry>
          <mesh>
            <scale>0.1 0.1 0.1</scale>
            <uri>model://dji/meshes/propeller_ccw.dae</uri>
          </mesh>
        </geometry>
        <material>
          <script>
            <name>Gazebo/Red</name>
            <uri>file://media/materials/scripts/gazebo.material</uri>
          </script>
        </material>
      </visual>
      <gravity>1</gravity>
      <velocity_decay/>
    </link>

    <joint name='rotor_0_joint' type='revolute'>
      <child>rotor_0</child>
      <parent>base_link</parent>
      <axis>
        <xyz>0 0 1</xyz>
        <limit>
          <lower>-1e+16</lower>
          <upper>1e+16</upper>
        </limit>
        <dynamics>
          <spring_reference>0</spring_reference>
          <spring_stiffness>0</spring_stiffness>
        </dynamics>
        <use_parent_model_frame>1</use_parent_model_frame>
      </axis>
    </joint>

    <link name='rotor_1'>
      <pose>-0.232 0.232 0.034 0 0 0</pose>
      <inertial>
        <pose>0 0 0 0 0 0</pose>
        <mass>0.005</mass>
        <inertia>
          <ixx>9.75e-07</ixx>
          <ixy>0</ixy>
          <ixz>0</ixz>
          <iyy>4.17041e-05</iyy>
          <iyz>0</iyz>
          <izz>4.26041e-05</izz>
        </inertia>
      </inertial>
      <collision name='rotor_1_collision'>
        <pose>0 0 0 0 0 0</pose>
        <geometry>
          <cylinder>
            <length>0.005</length>
            <radius>0.1</radius>
          </cylinder>
        </geometry>
        <surface>
          <contact>
            <ode/>
          </contact>
          <friction>
            <ode/>
          </friction>
        </surface>
      </collision>
      <visual name='rotor_1_visual'>
        <pose>0 0 0 0 0 0</pose>
        <geometry>
          <mesh>
            <scale>0.1 0.1 0.1</scale>
            <uri>model://dji/meshes/propeller_ccw.dae</uri>
          </mesh>
        </geometry>
        <material>
          <script>
            <name>Gazebo/Black</name>
            <uri>file://media/materials/scripts/gazebo.material</uri>
          </script>
        </material>
      </visual>
      <gravity>1</gravity>
      <velocity_decay/>
    </link>
    <joint name='rotor_1_joint' type='revolute'>
      <child>rotor_1</child>
      <parent>base_link</parent>
      <axis>
        <xyz>0 0 1</xyz>
        <limit>
          <lower>-1e+16</lower>
          <upper>1e+16</upper>
        </limit>
        <dynamics>
          <spring_reference>0</spring_reference>
          <spring_stiffness>0</spring_stiffness>
        </dynamics>
        <use_parent_model_frame>1</use_parent_model_frame>
      </axis>
    </joint>

    <link name='rotor_2'>
      <pose>0.232 0.232 0.034 0 0 0</pose>
      <inertial>
        <pose>0 0 0 0 0 0</pose>
        <mass>0.005</mass>
        <inertia>
          <ixx>9.75e-07</ixx>
          <ixy>0</ixy>
          <ixz>0</ixz>
          <iyy>4.17041e-05</iyy>
          <iyz>0</iyz>
          <izz>4.26041e-05</izz>
        </inertia>
      </inertial>
      <collision name='rotor_2_collision'>
        <pose>0 0 0 0 0 0</pose>
        <geometry>
          <cylinder>
            <length>0.005</length>
            <radius>0.1</radius>
          </cylinder>
        </geometry>
        <surface>
          <contact>
            <ode/>
          </contact>
          <friction>
            <ode/>
          </friction>
        </surface>
      </collision>
      <visual name='rotor_2_visual'>
        <pose>0 0 0 0 0 0</pose>
        <geometry>
          <mesh>
            <scale>0.1 0.1 0.1</scale>
            <uri>model://dji/meshes/propeller_cw.dae</uri>
          </mesh>
        </geometry>
        <material>
          <script>
            <name>Gazebo/Red</name>
            <uri>file://media/materials/scripts/gazebo.material</uri>
          </script>
        </material>
      </visual>
      <gravity>1</gravity>
      <velocity_decay/>
    </link>
    <joint name='rotor_2_joint' type='revolute'>
      <child>rotor_2</child>
      <parent>base_link</parent>
      <axis>
        <xyz>0 0 1</xyz>
        <limit>
          <lower>-1e+16</lower>
          <upper>1e+16</upper>
        </limit>
        <dynamics>
          <spring_reference>0</spring_reference>
          <spring_stiffness>0</spring_stiffness>
        </dynamics>
        <use_parent_model_frame>1</use_parent_model_frame>
      </axis>
    </joint>
    
    <link name='rotor_3'>
      <pose>-0.232 -0.232 0.034 0 0 0</pose>
      <inertial>
        <pose>0 0 0 0 0 0</pose>
        <mass>0.005</mass>
        <inertia>
          <ixx>9.75e-07</ixx>
          <ixy>0</ixy>
          <ixz>0</ixz>
          <iyy>4.17041e-05</iyy>
          <iyz>0</iyz>
          <izz>4.26041e-05</izz>
        </inertia>
      </inertial>
      <collision name='rotor_3_collision'>
        <pose>0 0 0 0 0 0</pose>
        <geometry>
          <cylinder>
            <length>0.005</length>
            <radius>0.1</radius>
          </cylinder>
        </geometry>
        <surface>
          <contact>
            <ode/>
          </contact>
          <friction>
            <ode/>
          </friction>
        </surface>
      </collision>
      <visual name='rotor_3_visual'>
        <pose>0 0 0 0 0 0</pose>
        <geometry>
          <mesh>
            <scale>0.1 0.1 0.1</scale>
            <uri>model://dji/meshes/propeller_cw.dae</uri>
          </mesh>
        </geometry>
        <material>
          <script>
            <name>Gazebo/Black</name>
            <uri>file://media/materials/scripts/gazebo.material</uri>
          </script>
        </material>
      </visual>
      <gravity>1</gravity>
      <velocity_decay/>
    </link>
    <joint name='rotor_3_joint' type='revolute'>
      <child>rotor_3</child>
      <parent>base_link</parent>
      <axis>
        <xyz>0 0 1</xyz>
        <limit>
          <lower>-1e+16</lower>
          <upper>1e+16</upper>
        </limit>
        <dynamics>
          <spring_reference>0</spring_reference>
          <spring_stiffness>0</spring_stiffness>
        </dynamics>
        <use_parent_model_frame>1</use_parent_model_frame>
      </axis>
    </joint>

    <!-- Plugin to control differential locomotion-->
  <plugin
        filename="ignition-gazebo-multicopter-motor-model-system"
        name="ignition::gazebo::systems::MulticopterMotorModel">
        <robotNamespace>dji</robotNamespace>
        <jointName>rotor_0_joint</jointName>
        <linkName>rotor_0</linkName>
        <turningDirection>ccw</turningDirection>
        <timeConstantUp>0.0125</timeConstantUp>
        <timeConstantDown>0.025</timeConstantDown>
        <maxRotVelocity>20000.0</maxRotVelocity>
        <motorConstant>8.54858e-06</motorConstant>
        <momentConstant>0.016</momentConstant>
        <commandSubTopic>gazebo/command/motor_speed</commandSubTopic>
        <motorNumber>0</motorNumber>
        <rotorDragCoefficient>8.06428e-05</rotorDragCoefficient>
        <rollingMomentCoefficient>1e-06</rollingMomentCoefficient>
        <motorSpeedPubTopic>motor_speed/0</motorSpeedPubTopic>
        <rotorVelocitySlowdownSim>1</rotorVelocitySlowdownSim>
        <motorType>velocity</motorType>
      </plugin>
      <plugin
        filename="ignition-gazebo-multicopter-motor-model-system"
        name="ignition::gazebo::systems::MulticopterMotorModel">
        <robotNamespace>dji</robotNamespace>
        <jointName>rotor_1_joint</jointName>
        <linkName>rotor_1</linkName>
        <turningDirection>ccw</turningDirection>
        <timeConstantUp>0.0125</timeConstantUp>
        <timeConstantDown>0.025</timeConstantDown>
        <maxRotVelocity>20000.0</maxRotVelocity>
        <motorConstant>8.54858e-06</motorConstant>
        <momentConstant>0.016</momentConstant>
        <commandSubTopic>gazebo/command/motor_speed</commandSubTopic>
        <motorNumber>1</motorNumber>
        <rotorDragCoefficient>8.06428e-05</rotorDragCoefficient>
        <rollingMomentCoefficient>1e-06</rollingMomentCoefficient>
        <motorSpeedPubTopic>motor_speed/1</motorSpeedPubTopic>
        <rotorVelocitySlowdownSim>1</rotorVelocitySlowdownSim>
        <motorType>velocity</motorType>
      </plugin>
      <plugin
        filename="ignition-gazebo-multicopter-motor-model-system"
        name="ignition::gazebo::systems::MulticopterMotorModel">
        <robotNamespace>dji</robotNamespace>
        <jointName>rotor_2_joint</jointName>
        <linkName>rotor_2</linkName>
        <turningDirection>cw</turningDirection>
        <timeConstantUp>0.0125</timeConstantUp>
        <timeConstantDown>0.025</timeConstantDown>
        <maxRotVelocity>20000.0</maxRotVelocity>
        <motorConstant>8.54858e-06</motorConstant>
        <momentConstant>0.016</momentConstant>
        <commandSubTopic>gazebo/command/motor_speed</commandSubTopic>
        <motorNumber>2</motorNumber>
        <rotorDragCoefficient>8.06428e-05</rotorDragCoefficient>
        <rollingMomentCoefficient>1e-06</rollingMomentCoefficient>
        <motorSpeedPubTopic>motor_speed/2</motorSpeedPubTopic>
        <rotorVelocitySlowdownSim>1</rotorVelocitySlowdownSim>
        <motorType>velocity</motorType>
      </plugin>
      <plugin
        filename="ignition-gazebo-multicopter-motor-model-system"
        name="ignition::gazebo::systems::MulticopterMotorModel">
        <robotNamespace>dji</robotNamespace>
        <jointName>rotor_3_joint</jointName>
        <linkName>rotor_3</linkName>
        <turningDirection>cw</turningDirection>
        <timeConstantUp>0.0125</timeConstantUp>
        <timeConstantDown>0.025</timeConstantDown>
        <maxRotVelocity>20000.0</maxRotVelocity>
        <motorConstant>8.54858e-06</motorConstant>
        <momentConstant>0.016</momentConstant>
        <commandSubTopic>gazebo/command/motor_speed</commandSubTopic>
        <motorNumber>3</motorNumber>
        <rotorDragCoefficient>8.06428e-05</rotorDragCoefficient>
        <rollingMomentCoefficient>1e-06</rollingMomentCoefficient>
        <motorSpeedPubTopic>motor_speed/3</motorSpeedPubTopic>
        <rotorVelocitySlowdownSim>1</rotorVelocitySlowdownSim>
        <motorType>velocity</motorType>
      </plugin>

      <plugin
        filename="ignition-gazebo-odometry-publisher-system"
        name="ignition::gazebo::systems::OdometryPublisher">
        <dimensions>3</dimensions>
      </plugin>

  </model>
</sdf>
